Workbook

Sheet README
A1: CRITICAL SUPPLIER PERFORMANCE REVIEW — Q2 2026
A2: File khusus Q2 2026 (terpisah dari file Q1 2026)
A5: 1. ISI FILE INI
A6: • RAW DATA Q2 - 1 / Q2 - 2 — data mentah asli dari Microsoft Forms untuk periode Q2 2026 (jangan diedit, sumber data utama).
A7: • 21 sheet per-vendor (prefix 'Q2 ') — satu sheet per vendor, menampilkan SEMUA pertanyaan & jawaban asli (bukan cuma rata-rata), formula live ke RAW DATA.
A8: • RESULT Q2 — konsolidasi ke-21 vendor tsb + 1 baris untuk Arah Sejahtera Abadi (Kuncit) yang tidak mengisi assessment Q2.
A9: • HISTORICAL — tren skor 2024 s.d. Q2 2026, dengan Score + User Comment + Remarks per kuartal (sesuai format yang sudah baku dipakai sebelumnya, hanya dirapikan tampilannya).
A10: • DASHBOARD — cari vendor via dropdown, langsung muncul skor terkini, status, tren, riwayat performance per kuartal LENGKAP dengan comment-nya, grafik tren, dan tabel ringkasan semua vendor.
A11: • SUMMARY Q2 2026 — ringkasan angka: jumlah vendor dievaluasi, % evaluasi, status keseluruhan.
A13: 2. FILE INI TERPISAH DARI Q1 2026
A14: File 'SUPERMAN_Performance_Review_Q1_2026_REVAMPED.xlsx' yang sebelumnya dibuat adalah pegangan Q1 tersendiri dan TIDAK digabung ke file ini. HISTORICAL di file ini tetap menampilkan tren dari 2024 sampai Q1 2026 sebagai data referensi (angka historis, bukan link langsung ke file Q1), lalu kolom Q2 2026 baru yang formula-nya live ke RESULT Q2 di file ini sendiri.
A16: 3. KLARIFIKASI DARI DISKUSI SEBELUMNYA
... A29: Score > 4.99 → Exceptional | Score > 3.99 → Exceed Expectation | Score >= 2.99 → Meet Expectation | Score > 1.9 → Below Expectation | Score <= 1.9 → Unsatisfactory

Sheet DASHBOARD
A1: DASHBOARD — CRITICAL SUPPLIER PERFORMANCE REVIEW (Q2 2026)
A3: 🔍 Cari Vendor: | C3: INDOSAT - LAYANAN PBX BERBASISKAN CLOUD DENGAN TEKNOLOGI SIP TRUNK | J3: MatchRow
A4: (pilih dari dropdown, atau ketik sebagian nama) | J4: =IFERROR(MATCH($C$3,HISTORICAL!$AF$7:$AF$28,0)+6,"") -> 7
A6: Vendor | B6: Service | C6: PIC Saat Ini | D6: Skor Q2 2026 | E6: Status Q2 2026 | F6: Skor Q1 2026 | G6: Tren vs Q1
A7: =IF($J$4="","",INDEX(HISTORICAL!B:B,$J$4)) -> INDOSAT | B7: =IF($J$4="","",INDEX(HISTORICAL!C:C,$J$4)) -> LAYANAN PBX BERBASISKAN CLOUD DENGAN TEKNOLOGI SIP TRUNK | C7: =IF($J$4="","",IFERROR(INDEX(HISTORICAL!AG:AG,$J$4),"-")) -> Nuril HUDHA | D7: =IF($J$4="","",INDEX(HISTORICAL!AC:AC,$J$4)) -> 3.4394737 | E7: =IF($J$4="","",INDEX(HISTORICAL!AE:AE,$J$4)) -> Meet Expectation | F7: =IF($J$4="","",INDEX(HISTORICAL!Z:Z,$J$4)) -> 3.3184211 | G7: =IF($J$4="","",IF(OR(NOT(ISNUMBER(D7)),NOT(ISNUMBER(F7))),"n/a",IF(D7>F7,"▲ Naik "&TEXT(D7-F7,"0.00"),IF(D7<F7,"▼ Turun "&TEXT(F7-D7,"0.00"),"— Stabil")))) -> ▲ Naik 0.12
A10: RIWAYAT PERFORMANCE PER KUARTAL
A11: Periode | B11: Skor | C11: Status | D11: User Comment / Remarks | I11: ChartVal
A12: 2024 Q1 | B12: =IF($J$4="","",IF(OR(INDEX(HISTORICAL!D:D,$J$4)="N/A",INDEX(HISTORICAL!D:D,$J$4)=0),"-",INDEX(HISTORICAL!D:D,$J$4))) -> 3 | C12: =IF($J$4="","",IF(INDEX(HISTORICAL!E:E,$J$4)="","-",INDEX(HISTORICAL!E:E,$J$4))) -> Meet Expectation | D12: ="(tidak ada data comment terpisah untuk periode ini)" -> (tidak ada data comment terpisah untuk periode ini) | I12: =IFERROR(IF(B12="-",NA(),B12),NA()) -> 3
A13: 2024 Q2 | B13: =IF($J$4="","",IF(OR(INDEX(HISTORICAL!F:F,$J$4)="N/A",INDEX(HISTORICAL!F:F,$J$4)=0),"-",INDEX(HISTORICAL!F:F,$J$4))) -> 3 | C13: =IF($J$4="","",IF(INDEX(HISTORICAL!G:G,$J$4)="","-",INDEX(HISTORICAL!G:G,$J$4))) -> Meet Expectation | D13: ="(tidak ada data comment terpisah untuk periode ini)" -> (tidak ada data comment terpisah untuk periode ini) | I13: =IFERROR(IF(B13="-",NA(),B13),NA()) -> 3
A14: 2024 Q3 | B14: =IF($J$4="","",IF(OR(INDEX(HISTORICAL!H:H,$J$4)="N/A",INDEX(HISTORICAL!H:H,$J$4)=0),"-",INDEX(HISTORICAL!H:H,$J$4))) -> 2.95 | C14: =IF($J$4="","",IF(INDEX(HISTORICAL!I:I,$J$4)="","-",INDEX(HISTORICAL!I:I,$J$4))) -> Below Expectation | D14: ="(tidak ada data comment terpisah untuk periode ini)" -> (tidak ada data comment terpisah untuk periode ini) | I14: =IFERROR(IF(B14="-",NA(),B14),NA()) -> 2.95
A15: 2024 Q4 | B15: =IF($J$4="","",IF(OR(INDEX(HISTORICAL!J:J,$J$4)="N/A",INDEX(HISTORICAL!J:J,$J$4)=0),"-",INDEX(HISTORICAL!J:J,$J$4))) -> 3 | C15: =IF($J$4="","",IF(INDEX(HISTORICAL!K:K,$J$4)="","-",INDEX(HISTORICAL!K:K,$J$4))) -> Meet Expectation | D15: ="(tidak ada data comment terpisah untuk periode ini)" -> (tidak ada data comment terpisah untuk periode ini) | I15: =IFERROR(IF(B15="-",NA(),B15),NA()) -> 3
A16: 2025 Q1 | B16: =IF($J$4="","",IF(OR(INDEX(HISTORICAL!L:L,$J$4)="N/A",INDEX(HISTORICAL!L:L,$J$4)=0),"-",INDEX(HISTORICAL!L:L,$J$4))) -> 2.345 | C16: =IF($J$4="","",IF(INDEX(HISTORICAL!N:N,$J$4)="","-",INDEX(HISTORICAL!N:N,$J$4))) -> Below Expectation | D16: =IF($J$4="","",IF(INDEX(HISTORICAL!M:M,$J$4)="","-",INDEX(HISTORICAL!M:M,$J$4))) -> Need improvement for the part of fair and to be more responsive to solve issues. | I16: =IFERROR(IF(B16="-",NA(),B16),NA()) -> 2.345
A17: 2025 Q2 | B17: =IF($J$4="","",IF(OR(INDEX(HISTORICAL!O:O,$J$4)="N/A",INDEX(HISTORICAL!O:O,$J$4)=0),"-",INDEX(HISTORICAL!O:O,$J$4))) -> 1.99 | C17: =IF($J$4="","",IF(INDEX(HISTORICAL!Q:Q,$J$4)="","-",INDEX(HISTORICAL!Q:Q,$J$4))) -> Below Expectation | D17: =IF($J$4="","",IF(INDEX(HISTORICAL!P:P,$J$4)="","-",INDEX(HISTORICAL!P:P,$J$4))) -> 1. Dashboard access to required user 2. Response time to be improved as promised 3. To be more proactive in update the progress 4. To provide regular report (usage, recording, etc) | I17: =IFERROR(IF(B17="-",NA(),B17),NA()) -> 1.99
A18: 2025 Q3 | B18: =IF($J$4="","",IF(OR(INDEX(HISTORICAL!R:R,$J$4)="N/A",INDEX(HISTORICAL!R:R,$J$4)=0),"-",INDEX(HISTORICAL!R:R,$J$4))) -> 2.72 | C18: =IF($J$4="","",IF(INDEX(HISTORICAL!T:T,$J$4)="","-",INDEX(HISTORICAL!T:T,$J$4))) -> Below Expectation | D18: =IF($J$4="","",IF(INDEX(HISTORICAL!S:S,$J$4)="","-",INDEX(HISTORICAL!S:S,$J$4))) -> improve responsiveness when there is problem appear, and more proactive ask client follow up for the re-solution work or not after fixing. have plan maintenance and communicated earlier to client so client can aware about maintenance process. | I18: =IFERROR(IF(B18="-",NA(),B18),NA()) -> 2.72
A19: 2025 Q4 | B19: =IF($J$4="","",IF(OR(INDEX(HISTORICAL!W:W,$J$4)="N/A",INDEX(HISTORICAL!W:W,$J$4)=0),"-",INDEX(HISTORICAL!W:W,$J$4))) -> 2.9825 | C19: =IF($J$4="","",IF(INDEX(HISTORICAL!Y:Y,$J$4)="","-",INDEX(HISTORICAL!Y:Y,$J$4))) -> BELOW EXPECTATION | D19: =IF($J$4="","",IF(INDEX(HISTORICAL!X:X,$J$4)="","-",INDEX(HISTORICAL!X:X,$J$4))) -> PLEASE KINDLY IMPROVE REQUIRED REPORT DELIVERY AS AGREED WITH ANALYZED DATA FOR BUSINESS CONSIDERATION. | I19: =IFERROR(IF(B19="-",NA(),B19),NA()) -> 2.9825
A20: 2026 Q1 | B20: =IF($J$4="","",IF(OR(INDEX(HISTORICAL!Z:Z,$J$4)="N/A",INDEX(HISTORICAL!Z:Z,$J$4)=0),"-",INDEX(HISTORICAL!Z:Z,$J$4))) -> 3.3184211 | C20: =IF($J$4="","",IF(INDEX(HISTORICAL!AB:AB,$J$4)="","-",INDEX(HISTORICAL!AB:AB,$J$4))) -> MEET EXPECTATION | D20: =IF($J$4="","",IF(INDEX(HISTORICAL!AA:AA,$J$4)="","-",INDEX(HISTORICAL!AA:AA,$J$4))) -> The performance is getting better, please keep improve the performance. | I20: =IFERROR(IF(B20="-",NA(),B20),NA()) -> 3.3184211
A21: 2026 Q2 | B21: =IF($J$4="","",IF(OR(INDEX(HISTORICAL!AC:AC,$J$4)="N/A",INDEX(HISTORICAL!AC:AC,$J$4)=0),"-",INDEX(HISTORICAL!AC:AC,$J$4))) -> 3.4394737 | C21: =IF($J$4="","",IF(INDEX(HISTORICAL!AE:AE,$J$4)="","-",INDEX(HISTORICAL!AE:AE,$J$4))) -> Meet Expectation | D21: =IF($J$4="","",IF(INDEX(HISTORICAL!AD:AD,$J$4)="","-",INDEX(HISTORICAL!AD:AD,$J$4))) -> Vendor performance is generally acceptable and aligns with the expected level of service. While the engagement has been positive overall, improvements are needed in feature enhancement, dashboard capabilities, and the regularity of report updates. Better preparation in deployment and timely reporting would help increase the overall value and effectiveness of the service. | I21: =IFERROR(IF(B21="-",NA(),B21),NA()) -> 3.4394737
A24: RINGKASAN SEMUA VENDOR (Q2 2026)
A25: No | B25: Vendor | C25: Service | D25: Skor Q1 2026 | E25: Skor Q2 2026 | F25: Status Terkini | G25: Tren
A26: 1 | B26: =HISTORICAL!B7 -> INDOSAT | C26: =HISTORICAL!C7 -> LAYANAN PBX BERBASISKAN CLOUD DENGAN TEKNOLOGI SIP TRUNK | D26: =IF(OR(HISTORICAL!Z7="N/A",HISTORICAL!Z7=0),"-",HISTORICAL!Z7) -> 3.3184211 | E26: =IF(HISTORICAL!AC7="N/A","-",HISTORICAL!AC7) -> 3.4394737 | F26: =IF(HISTORICAL!AE7<>"N/A",HISTORICAL!AE7,IF(HISTORICAL!AB7<>"N/A",HISTORICAL!AB7,"N/A")) -> Meet Expectation | G26: =IF(OR(NOT(ISNUMBER(D26)),NOT(ISNUMBER(E26))),"-",IF(E26>D26,"▲",IF(E26<D26,"▼","—"))) -> ▲
A27: 2 | B27: =HISTORICAL!B8 -> INFORMASI TEKNOLOGI INDONESIA | C27: =HISTORICAL!C8 -> PENYEDIAAN JASA SMS BROADCAST DAN JASA SMS PULL; CONNECTIVITY PRIMARY LINK | D27: =IF(OR(HISTORICAL!Z8="N/A",HISTORICAL!Z8=0),"-",HISTORICAL!Z8) -> 3 | E27: =IF(HISTORICAL!AC8="N/A","-",HISTORICAL!AC8) -> 3 | F27: =IF(HISTORICAL!AE8<>"N/A",HISTORICAL!AE8,IF(HISTORICAL!AB8<>"N/A",HISTORICAL!AB8,"N/A")) -> Meet Expectation | G27: =IF(OR(NOT(ISNUMBER(D27)),NOT(ISNUMBER(E27))),"-",IF(E27>D27,"▲",IF(E27<D27,"▼","—"))) -> —
A28: 3 | B28: =HISTORICAL!B9 -> MITRA INTEGRASI INFORMATIKA | C28: =HISTORICAL!C9 -> SFDC MAINTENANCE | D28: =IF(OR(HISTORICAL!Z9="N/A",HISTORICAL!Z9=0),"-",HISTORICAL!Z9) -> 4.8294872 | E28: =IF(HISTORICAL!AC9="N/A","-",HISTORICAL!AC9) -> 4.7487179 | F28: =IF(HISTORICAL!AE9<>"N/A",HISTORICAL!AE9,IF(HISTORICAL!AB9<>"N/A",HISTORICAL!AB9,"N/A")) -> Exceed Expectation | G28: =IF(OR(NOT(ISNUMBER(D28)),NOT(ISNUMBER(E28))),"-",IF(E28>D28,"▲",IF(E28<D28,"▼","—"))) -> ▼
A29: 4 | B29: =HISTORICAL!B10 -> MULTIFILING MITRA INDONESIA | C29: =HISTORICAL!C10 -> RECORD MANAGEMENT SERVICE | D29: =IF(OR(HISTORICAL!Z10="N/A",HISTORICAL!Z10=0),"-",HISTORICAL!Z10) -> 3.0318182 | E29: =IF(HISTORICAL!AC10="N/A","-",HISTORICAL!AC10) -> 3 | F29: =IF(HISTORICAL!AE10<>"N/A",HISTORICAL!AE10,IF(HISTORICAL!AB10<>"N/A",HISTORICAL!AB10,"N/A")) -> Meet Expectation | G29: =IF(OR(NOT(ISNUMBER(D29)),NOT(ISNUMBER(E29))),"-",IF(E29>D29,"▲",IF(E29<D29,"▼","—"))) -> ▼
A30: 5 | B30: =HISTORICAL!B11 -> CIPTADRA SOFTINDO | C30: =HISTORICAL!C11 -> PEMELIHARAAN PERANGKAT LUNAK AXITS DAN PERANGKAT LUNAK DMTM | D30: =IF(OR(HISTORICAL!Z11="N/A",HISTORICAL!Z11=0),"-",HISTORICAL!Z11) -> 4 | E30: =IF(HISTORICAL!AC11="N/A","-",HISTORICAL!AC11) -> 4.3 | F30: =IF(HISTORICAL!AE11<>"N/A",HISTORICAL!AE11,IF(HISTORICAL!AB11<>"N/A",HISTORICAL!AB11,"N/A")) -> Exceed Expectation | G30: =IF(OR(NOT(ISNUMBER(D30)),NOT(ISNUMBER(E30))),"-",IF(E30>D30,"▲",IF(E30<D30,"▼","—"))) -> ▲
A31: 6 | B31: =HISTORICAL!B12 -> INMOTION INOVASI TEKNOLOGI | C31: =HISTORICAL!C12 -> JASA APLIKASI CHATBOT DAN LIVE CHAT | D31: =IF(OR(HISTORICAL!Z12="N/A",HISTORICAL!Z12=0),"-",HISTORICAL!Z12) -> 4 | E31: =IF(HISTORICAL!AC12="N/A","-",HISTORICAL!AC12) -> 4 | F31: =IF(HISTORICAL!AE12<>"N/A",HISTORICAL!AE12,IF(HISTORICAL!AB12<>"N/A",HISTORICAL!AB12,"N/A")) -> Exceed Expectation | G31: =IF(OR(NOT(ISNUMBER(D31)),NOT(ISNUMBER(E31))),"-",IF(E31>D31,"▲",IF(E31<D31,"▼","—"))) -> —
A32: 7 | B32: =HISTORICAL!B13 -> SATRIA ANTARAN PRIMA TBK | C32: =HISTORICAL!C13 -> PENGIRIMAN POLIS DOKUMEN DAN PAKET DALAM NEGERI | D32: =IF(OR(HISTORICAL!Z13="N/A",HISTORICAL!Z13=0),"-",HISTORICAL!Z13) -> 3 | E32: =IF(HISTORICAL!AC13="N/A","-",HISTORICAL!AC13) -> 3.2383333 | F32: =IF(HISTORICAL!AE13<>"N/A",HISTORICAL!AE13,IF(HISTORICAL!AB13<>"N/A",HISTORICAL!AB13,"N/A")) -> Meet Expectation | G32: =IF(OR(NOT(ISNUMBER(D32)),NOT(ISNUMBER(E32))),"-",IF(E32>D32,"▲",IF(E32<D32,"▼","—"))) -> ▲
A33: 8 | B33: =HISTORICAL!B14 -> SATRIA ANTARAN PRIMA TBK | C33: =HISTORICAL!C14 -> MAILING ROOM | D33: =IF(OR(HISTORICAL!Z14="N/A",HISTORICAL!Z14=0),"-",HISTORICAL!Z14) -> 3.4041667 | E33: =IF(HISTORICAL!AC14="N/A","-",HISTORICAL!AC14) -> 3.04375 | F33: =IF(HISTORICAL!AE14<>"N/A",HISTORICAL!AE14,IF(HISTORICAL!AB14<>"N/A",HISTORICAL!AB14,"N/A")) -> Meet Expectation | G33: =IF(OR(NOT(ISNUMBER(D33)),NOT(ISNUMBER(E33))),"-",IF(E33>D33,"▲",IF(E33<D33,"▼","—"))) -> ▼
A34: 9 | B34: =HISTORICAL!B15 -> TARGET SUKSES SINERGI | C34: =HISTORICAL!C15 -> PENGIRIMAN EMAIL MARKETING AUTOMATION | D34: =IF(OR(HISTORICAL!Z15="N/A",HISTORICAL!Z15=0),"-",HISTORICAL!Z15) -> 3.9 | E34: =IF(HISTORICAL!AC15="N/A","-",HISTORICAL!AC15) -> 2.9416667 | F34: =IF(HISTORICAL!AE15<>"N/A",HISTORICAL!AE15,IF(HISTORICAL!AB15<>"N/A",HISTORICAL!AB15,"N/A")) -> Below Expectation | G34: =IF(OR(NOT(ISNUMBER(D34)),NOT(ISNUMBER(E34))),"-",IF(E34>D34,"▲",IF(E34<D34,"▼","—"))) -> ▼
A35: 10 | B35: =HISTORICAL!B16 -> WIZ TECHNOLOGY INDONESIA | C35: =HISTORICAL!C16 -> VOICE BOT REMINDER CALL | D35: =IF(OR(HISTORICAL!Z16="N/A",HISTORICAL!Z16=0),"-",HISTORICAL!Z16) -> - | E35: =IF(HISTORICAL!AC16="N/A","-",HISTORICAL!AC16) -> 3.0875 | F35: =IF(HISTORICAL!AE16<>"N/A",HISTORICAL!AE16,IF(HISTORICAL!AB16<>"N/A",HISTORICAL!AB16,"N/A")) -> Meet Expectation | G35: =IF(OR(NOT(ISNUMBER(D35)),NOT(ISNUMBER(E35))),"-",IF(E35>D35,"▲",IF(E35<D35,"▼","—"))) -> -
A36: 11 | B36: =HISTORICAL!B17 -> KARYAPUTRA SURYAGEMILANG | C36: =HISTORICAL!C17 -> TELEMARKETING REVAMP PROJECT | D36: =IF(OR(HISTORICAL!Z17="N/A",HISTORICAL!Z17=0),"-",HISTORICAL!Z17) -> 3.0318182 | E36: =IF(HISTORICAL!AC17="N/A","-",HISTORICAL!AC17) -> 3.5393939 | F36: =IF(HISTORICAL!AE17<>"N/A",HISTORICAL!AE17,IF(HISTORICAL!AB17<>"N/A",HISTORICAL!AB17,"N/A")) -> Meet Expectation | G36: =IF(OR(NOT(ISNUMBER(D36)),NOT(ISNUMBER(E36))),"-",IF(E36>D36,"▲",IF(E36<D36,"▼","—"))) -> ▲
A37: 12 | B37: =HISTORICAL!B18 -> ARAH SEJAHTERA ABADI | C37: =HISTORICAL!C18 -> PERJANJIAN SEWA MENYEWA | D37: =IF(OR(HISTORICAL!Z18="N/A",HISTORICAL!Z18=0),"-",HISTORICAL!Z18) -> 2.9611111 | E37: =IF(HISTORICAL!AC18="N/A","-",HISTORICAL!AC18) -> - | F37: =IF(HISTORICAL!AE18<>"N/A",HISTORICAL!AE18,IF(HISTORICAL!AB18<>"N/A",HISTORICAL!AB18,"N/A")) -> Tidak Dievaluasi Q2 | G37: =IF(OR(NOT(ISNUMBER(D37)),NOT(ISNUMBER(E37))),"-",IF(E37>D37,"▲",IF(E37<D37,"▼","—"))) -> -
... A47: 22 | B47: =HISTORICAL!B28 -> ESHAEL Indonesia | C47: =HISTORICAL!C28 -> Talent Assesment | D47: =IF(OR(HISTORICAL!Z28="N/A",HISTORICAL!Z28=0),"-",HISTORICAL!Z28) -> - | E47: =IF(HISTORICAL!AC28="N/A","-",HISTORICAL!AC28) -> 4.6083333 | F47: =IF(HISTORICAL!AE28<>"N/A",HISTORICAL!AE28,IF(HISTORICAL!AB28<>"N/A",HISTORICAL!AB28,"N/A")) -> Exceed Expectation | G47: =IF(OR(NOT(ISNUMBER(D47)),NOT(ISNUMBER(E47))),"-",IF(E47>D47,"▲",IF(E47<D47,"▼","—"))) -> -

Sheet HISTORICAL
A1: HISTORICAL PERFORMANCE REVIEW — SEMUA VENDOR (2024 s.d. Q2 2026)
A2: Catatan: skor Q1 2026 untuk Satria Antaran Prima (Mailing Room) & Reycom Document Solution sudah DIKOREKSI dari laporan resmi sebelumnya (ditemukan bug formula/copy-paste di file asli Q1) — lihat sheet README untuk detail.
A4: No | B4: Vendor | C4: Service Scope | D4: 2024 | L4: 2025 | U4: Repetition of Below Expectation | V4: Catatan Repetisi | W4: 2025 - 2026 | AC4: 2026 (BARU)
D5: 2024 Q1 | F5: 2024 Q2 | H5: 2024 Q3 | J5: 2024 Q4 | L5: 2025 Q1 | O5: 2025 Q2 | R5: 2025 Q3 | W5: 2025 Q4 | Z5: 2026 Q1 | AC5: 2026 Q2
D6: Score | E6: Remarks | F6: Score | G6: Remarks | H6: Score | I6: Remarks | J6: Score | K6: Remarks | L6: Score | M6: User Comment | N6: Remarks | O6: Score | P6: User Comment | Q6: Remarks | R6: Score | S6: User Comment | T6: Remarks | W6: Score | X6: User Comment | Y6: Remarks | Z6: Score | AA6: User Comment | AB6: Remarks | AC6: Score | AD6: User Comment | AE6: Remarks | AF6: Search Key | AG6: PIC Q2 2026
A7: 1 | B7: INDOSAT | C7: LAYANAN PBX BERBASISKAN CLOUD DENGAN TEKNOLOGI SIP TRUNK | D7: 3 | E7: Meet Expectation | F7: 3 | G7: Meet Expectation | H7: 2.95 | I7: Below Expectation | J7: 3 | K7: Meet Expectation | L7: 2.345 | M7: Need improvement for the part of fair and to be more responsive to solve issues. | N7: Below Expectation | O7: 1.99 | P7: 1. Dashboard access to required user 2. Response time to be improved as promised 3. To be more proactive in update the progress 4. To provide regular report (usage, recording, etc) | Q7: Below Expectation | R7: 2.72 | S7: improve responsiveness when there is problem appear, and more proactive ask client follow up for the re-solution work or not after fixing. have plan maintenance and communicated earlier to client so client can aware about maintenance process. | T7: Below Expectation | U7: 3X | V7: Sudah dilakukan pemanggilan terhadap vendor yang bersangkutan dan pada Q3 terjadi perbaikan performance pada aspek kualitas jasa yang diberikan, dan pemenuhan timeline SLA | W7: 2.9825 | X7: PLEASE KINDLY IMPROVE REQUIRED REPORT DELIVERY AS AGREED WITH ANALYZED DATA FOR BUSINESS CONSIDERATION. | Y7: BELOW EXPECTATION | Z7: 3.3184211 | AA7: The performance is getting better, please keep improve the performance. | AB7: MEET EXPECTATION | AC7: =IFERROR(VALUE('RESULT Q2'!E9),"N/A") -> 3.4394737 | AD7: =IFERROR('RESULT Q2'!G9,"-") -> Vendor performance is generally acceptable and aligns with the expected level of service. While the engagement has been positive overall, improvements are needed in feature enhancement, dashboard capabilities, and the regularity of report updates. Better preparation in deployment and timely reporting would help increase the overall value and effectiveness of the service. | AE7: =IFERROR('RESULT Q2'!F9,"N/A") -> Meet Expectation | AF7: =B7&" - "&C7 -> INDOSAT - LAYANAN PBX BERBASISKAN CLOUD DENGAN TEKNOLOGI SIP TRUNK | AG7: =IFERROR('RESULT Q2'!D9,"-") -> Nuril HUDHA
A8: 2 | B8: INFORMASI TEKNOLOGI INDONESIA | C8: PENYEDIAAN JASA SMS BROADCAST DAN JASA SMS PULL; CONNECTIVITY PRIMARY LINK | D8: 3.78 | E8: Meet Expectation | F8: 4.21 | G8: Exceed Expectation | H8: 3 | I8: Meet Expectation | J8: 3 | K8: Meet Expectation | L8: 3 | M8: Sejauh ini untuk Vendor jaris tidak ada kendala, responsif. | N8: Meet Expectation | O8: 3 | P8: So far Jatis has provided good service | Q8: Meet Expectation | R8: 3 | S8: Secara keseluran service yang diberikan oleh JATIS baik | T8: Meet Expectation | U8: 0x | V8: - | W8: 3.0818182 | X8: STILL MEET REQUIREMENT | Y8: MEET EXPECTATION | Z8: 3 | AA8: Jatis has provided good service throughout this year | AB8: MEET EXPECTATION | AC8: =IFERROR(VALUE('RESULT Q2'!E6),"N/A") -> 3 | AD8: =IFERROR('RESULT Q2'!G6,"-") -> So far, Jatis Vendor has provided good service. Their response time is fast, and they are able to provide effective solutions whenever issues arise | AE8: =IFERROR('RESULT Q2'!F6,"N/A") -> Meet Expectation | AF8: =B8&" - "&C8 -> INFORMASI TEKNOLOGI INDONESIA - PENYEDIAAN JASA SMS BROADCAST DAN JASA SMS PULL; CONNECTIVITY PRIMARY LINK | AG8: =IFERROR('RESULT Q2'!D6,"-") -> Fifin SARINURLITA
A9: 3 | B9: MITRA INTEGRASI INFORMATIKA | C9: SFDC MAINTENANCE | D9: 3 | E9: Meet Expectation | F9: 3 | G9: Meet Expectation | H9: 3.96 | I9: Meet Expectation | J9: 3.65 | K9: Meet Expectation | L9: 3 | M9: 0 | N9: Meet Expectation | O9: 4.4166667 | P9: The response from the MII Team to all the issues and needs we encountered has been quite good. They were able to promptly provide workarounds and broad solutions. The PIC assigned to the project was very communicative and responsible. Please maintain this level of performance, as we truly rely on it. | Q9: Exceed Expectation | R9: 4.3538462 | S9: Good for MII, keep it up. | T9: Exceed Expectation | U9: 0x | V9: - | W9: 4.2730769 | X9: OVERALL, THE SUPPORT FROM MII IS VERY GOOD AND VERY HELPFUL, BOTH IN TERMS OF COMMUNICATION AND TECHNICAL ASPECTS, IT IS VERY EASY TO UNDERSTAND. | Y9: EXCEED EXPECTATION | Z9: 4.8294872 | AA9: verall, the level of support has been satisfactory. The improvements carried out were highly effective, and several demands were consistent with the initial assessment and expectations. | AB9: MEET EXPECTATION | AC9: =IFERROR(VALUE('RESULT Q2'!E13),"N/A") -> 4.7487179 | AD9: =IFERROR('RESULT Q2'!G13,"-") -> Respons terhadap issue maupun kebutuhan sudah cukup baik dan cepat. Support on-site juga sangat membantu dan responsif. Ke depannya, mungkin dapat lebih rutin memberikan update terkait progress kendala atau perbaikan yang sedang dilakukan, sehingga pihak terkait dapat mengetahui status terbaru dan lebih cepat menentukan langkah selanjutnya. | AE9: =IFERROR('RESULT Q2'!F13,"N/A") -> Exceed Expectation | AF9: =B9&" - "&C9 -> MITRA INTEGRASI INFORMATIKA - SFDC MAINTENANCE | AG9: =IFERROR('RESULT Q2'!D13,"-") -> Chandra Nugraha PUTRA
A10: 4 | B10: MULTIFILING MITRA INDONESIA | C10: RECORD MANAGEMENT SERVICE | D10: 3 | E10: Meet Expectation | F10: 4 | G10: Exceed Expectation | H10: 4 | I10: Exceed Expectation | J10: 3.65 | K10: Meet Expectation | L10: 3 | M10: - | N10: Meet Expectation | O10: 3 | P10: overall OK | Q10: Meet Expectation | R10: 3.9125 | S10: Untuk project destroy harga jangan mahal mahal | T10: Exceed Expectation | U10: 0x | V10: - | W10: 3.0693182 | X10: INOVASI FROM MMI FOR SIMPLIFY PROCESS STORAGE | Y10: MEET EXPECTATION | Z10: 3.0318182 | AA10: impprove innovation dan simplyfy process | AB10: MEET EXPECTATION | AC10: =IFERROR(VALUE('RESULT Q2'!E8),"N/A") -> 3 | AD10: =IFERROR('RESULT Q2'!G8,"-") -> .. | AE10: =IFERROR('RESULT Q2'!F8,"N/A") -> Meet Expectation | AF10: =B10&" - "&C10 -> MULTIFILING MITRA INDONESIA - RECORD MANAGEMENT SERVICE | AG10: =IFERROR('RESULT Q2'!D8,"-") -> Ibnu KUMALA
A11: 5 | B11: CIPTADRA SOFTINDO | C11: PEMELIHARAAN PERANGKAT LUNAK AXITS DAN PERANGKAT LUNAK DMTM | D11: 4.9 | E11: Exceed Expectation | F11: 4.73 | G11: Exceed Expectation | H11: 3.38 | I11: Meet Expectation | J11: 3 | K11: Meet Expectation | L11: 3.975 | M11: Ciptadra saat ini sudah sangat membantu IT AMFS apabila ada Issue atau Problem yang terjadi di DMTM dengan cepat. | N11: Exceed Expectation | O11: 3.675 | P11: Ciptadra sudah bekerja dengan baik apabila ada Issue terjadi, sangat fast Response. | Q11: Meet Expectation | R11: 3.75 | S11: - | T11: Meet Expectation | U11: 0x | V11: - | W11: 4.2 | X11: - | Y11: EXCEED EXPECTATION | Z11: 4 | AA11: Performance is Good | AB11: MEET EXPECTATION | AC11: =IFERROR(VALUE('RESULT Q2'!E10),"N/A") -> 4.3 | AD11: =IFERROR('RESULT Q2'!G10,"-") -> Ciptadra selalu fast response ketika ada incident yang terjadi di DMTM | AE11: =IFERROR('RESULT Q2'!F10,"N/A") -> Exceed Expectation | AF11: =B11&" - "&C11 -> CIPTADRA SOFTINDO - PEMELIHARAAN PERANGKAT LUNAK AXITS DAN PERANGKAT LUNAK DMTM | AG11: =IFERROR('RESULT Q2'!D10,"-") -> Raninta MAHARDI
A12: 6 | B12: INMOTION INOVASI TEKNOLOGI | C12: JASA APLIKASI CHATBOT DAN LIVE CHAT | D12: 3 | E12: Meet Expectation | F12: 3 | G12: Meet Expectation | H12: 3.09 | I12: Meet Expectation | J12: 3 | K12: Meet Expectation | L12: 2.121875 | M12: More responsive in solving problems and always providing information on the latest features to support future customer service. | N12: Below Expectation | O12: 2.9890625 | P12: Maintain the consistency and communication that has been established. Always take the initiative to provide the latest information regarding developments in the Live Chat service. | Q12: Below Expectation | R12: 3 | S12: Tetap selalu berikan Service yang Terbaik | T12: Meet Expectation | U12: 0x | V12: Sudah dilakukan pemanggilan terhadap vendor yang bersangkutan dan pada Q3 terjadi perbaikan performance | W12: 3.65 | X12: - | Y12: MEET EXPECTATION | Z12: 4 | AA12: continue performing thorough and frequent periodic checks to ensure that during service hours, there are no issues that could disrupt operations and resolve the remaining unresolved 401 issue Berikan umpan balik Anda tentang BizChat | AB12: MEET EXPECTATION | AC12: =IFERROR(VALUE('RESULT Q2'!E12),"N/A") -> 4 | AD12: =IFERROR('RESULT Q2'!G12,"-") -> Tetap up to date dan helpful | AE12: =IFERROR('RESULT Q2'!F12,"N/A") -> Exceed Expectation | AF12: =B12&" - "&C12 -> INMOTION INOVASI TEKNOLOGI - JASA APLIKASI CHATBOT DAN LIVE CHAT | AG12: =IFERROR('RESULT Q2'!D12,"-") -> Djoko DJOKO
A13: 7 | B13: SATRIA ANTARAN PRIMA TBK | C13: PENGIRIMAN POLIS DOKUMEN DAN PAKET DALAM NEGERI | D13: 3.75 | E13: Meet Expectation | F13: 3.83 | G13: Meet Expectation | H13: 2.74 | I13: Below Expectation | J13: 2.725 | K13: Below Expectation | L13: 2.86 | M13: User 1: ada progress positif dari SAP untuk memperbaiki apa yang kurang di periode sebelumnya. User 2: late respon terhadap keluhan pickup pengiriman dan validasi pengiriman dari PIC Unie. Draft invoice yang dikirimkan blm tertata dengan baik atau sesuai dengan kesamaan data dari User. | N13: Below Expectation | O13: 2.6166667 | P13: - SAP should be improve the quality of its couriers regarding accuracy of delivery status. - komunikasi dgn Unie sangat sulit, slow respons, invoice yg dikirimkan juga tidak ada respon dan updatenya ketika sudah di reminder. pickup dokumen secara manual (tidak menggunakan sistem) masih berjalan dan diterima oleh SAP. | Q13: Below Expectation | R13: 2.5 | S13: User 1: invoice periode maret-juni 2025 tdk ada update. update status informasi pengiriman tidak valid (fake shipment), kendala akun tidak dapat melakukan input, pickup manual masih terus berjalan (no commit). dah laah caapee User 2: sudah ada kemajuan mengenai respon terhadap complain handling oleh SAP | T13: Below Expectation | U13: 5X | V13: Pada periode Q2, Business User memberikan konfirmasi bahwa SAP diberi penilaian positif atas adanya perubahan dari proses pickup dokumen dan pengiriman invoice sebagai tanggapan kepada procurement ketika procurement memberikan masukan untuk melakukan penggantian vendor. Pada periode Q3, User kembali memberikan nilai below expectation dan akan dilakukan pemanggilan kepada vendor terkait. Paralel dengan proses tersebut, procurement melakukan arrangement untuk pemilihan vendor alternatif atas kebutuhan courier services. | W13: 2.9611111 | X13: VEMDOR SAP ADA PENINGKATAN TERUTAMA DI KOMUNIKASI PIC NYA | Y13: BELOW EXPECTATION | Z13: 3 | AA13: SAP has provided excellent service throughout this year | AB13: MEET EXPECTATION | AC13: =IFERROR(VALUE('RESULT Q2'!E7),"N/A") -> 3.2383333 | AD13: =IFERROR('RESULT Q2'!G7,"-") -> SAP has shown improvement in terms of reporting and provides a fast response whenever issues arise. | 1. untuk detail status pengiriman dokumen/barang harus diberikan keterangan penerima dengan lengkap dan jelas; 2. Maks. SLA pengiriman harus memenuhi sesuai dengan yang ditetapkan yaitu <5% not meet SLA; 3. Invoice biaya pengiriman dikirimkan ke user yang sesuai dan dikirimkan tidak melebihi periode yang ditetapkan. 4. Report Stock sesuai dengan real stock di warehouse. | AE13: =IFERROR('RESULT Q2'!F7,"N/A") -> Meet Expectation | AF13: =B13&" - "&C13 -> SATRIA ANTARAN PRIMA TBK - PENGIRIMAN POLIS DOKUMEN DAN PAKET DALAM NEGERI | AG13: =IFERROR('RESULT Q2'!D7,"-") -> Fifin SARINURLITA, Novia Laras SANTI
A14: 8 | B14: SATRIA ANTARAN PRIMA TBK | C14: MAILING ROOM | D14: N/A | E14: N/A | F14: N/A | G14: N/A | H14: N/A | I14: N/A | J14: N/A | K14: N/A | L14: 3 | M14: - | N14: Meet Expectation | O14: N/A | P14: N/A | Q14: N/A | R14: 3.9125 | S14: tingkatkan lebih performancenya | T14: Exceed Expectation | U14: 0x | V14: - | W14: 3.05 | X14: NEED INOVATION FROM SAP FOR SIMPLIFY PROCESS AT AXA MANDIRI MAILING ROOM | Y14: MEET EXPECTATION | Z14: 3.4041667 | AA14: Over all mailing ok, please improve coordinated with Headoffice team for reduce complain/misscomm (ex case overseas shipment ) | AB14: MEET EXPECTATION | AC14: =IFERROR(VALUE('RESULT Q2'!E5),"N/A") -> 3.04375 | AD14: =IFERROR('RESULT Q2'!G5,"-") -> improve inisiatsis | AE14: =IFERROR('RESULT Q2'!F5,"N/A") -> Meet Expectation | AF14: =B14&" - "&C14 -> SATRIA ANTARAN PRIMA TBK - MAILING ROOM | AG14: =IFERROR('RESULT Q2'!D5,"-") -> Ibnu KUMALA
A15: 9 | B15: TARGET SUKSES SINERGI | C15: PENGIRIMAN EMAIL MARKETING AUTOMATION | D15: 2.85 | E15: Below Expectation | F15: 3.28 | G15: Meet Expectation | H15: 4 | I15: Exceed Expectation | J15: 3.3125 | K15: Meet Expectation | L15: 3.7444444 | M15: Overall our partnership going well | N15: Meet Expectation | O15: 4 | P15: Please keep up the good work! | Q15: Exceed Expectation | R15: 3 | S15: Overall Good | T15: Meet Expectation | U15: 0x | V15: - | W15: 3.65 | X15: GOOD | Y15: MEET EXPECTATION | Z15: 3.9 | AA15: Harganya buat next contrac please murahin ya | AB15: MEET EXPECTATION | AC15: =IFERROR(VALUE('RESULT Q2'!E11),"N/A") -> 2.9416667 | AD15: =IFERROR('RESULT Q2'!G11,"-") -> Secara keseluruhan, MTarget telah memberikan dukungan yang baik dalam operasional email campaign dan responsif dalam menangani kebutuhan maupun isu yang muncul. Namun, insiden kesalahan pengiriman email yang terjadi menunjukkan perlunya penguatan pada proses deployment, pengujian, serta validasi sebelum implementasi ke production. Ke depannya, kami berharap MTarget dapat memperkuat proses change management, quality assurance, dan kontrol terhadap segmentasi serta pengiriman email untuk meminimalkan risiko terjadinya insiden serupa. | AE15: =IFERROR('RESULT Q2'!F11,"N/A") -> Below Expectation | AF15: =B15&" - "&C15 -> TARGET SUKSES SINERGI - PENGIRIMAN EMAIL MARKETING AUTOMATION | AG15: =IFERROR('RESULT Q2'!D11,"-") -> Bella Friska DEPARI
A16: 10 | B16: WIZ TECHNOLOGY INDONESIA | C16: VOICE BOT REMINDER CALL | D16: 3 | E16: Meet Expectation | F16: 3.61 | G16: Meet Expectation | H16: 3.4 | I16: Meet Expectation | J16: 3.0875 | K16: Meet Expectation | L16: 3.0388889 | M16: so far wiz.AI sudah memenuhi apa yang menjadi kebutuhan kami | N16: Meet Expectation | O16: 3.5444444 | P16: needs better communication for quicker responses. | Q16: Meet Expectation | R16: 3 | S16: sudah baik | T16: Meet Expectation | U16: 0x | V16: - | W16: 3.46875 | X16: WE EXPECT INITIATIVE TO BE TAKEN IN IMPLEMENTING MITIGATION MEASURES AND IN ACCELERATING THE PROCESS WITHIN COLLABORATION WITH WIZ AI. | Y16: MEET EXPECTATION | Z16: 0 | AA16: 0 | AC16: =IFERROR(VALUE('RESULT Q2'!E19),"N/A") -> 3.0875 | AD16: =IFERROR('RESULT Q2'!G19,"-") -> To ensure a smooth process, we need to move faster and maintain effective communication | AE16: =IFERROR('RESULT Q2'!F19,"N/A") -> Meet Expectation | AF16: =B16&" - "&C16 -> WIZ TECHNOLOGY INDONESIA - VOICE BOT REMINDER CALL | AG16: =IFERROR('RESULT Q2'!D19,"-") -> Ravika OKTAVIANI
A17: 11 | B17: KARYAPUTRA SURYAGEMILANG | C17: TELEMARKETING REVAMP PROJECT | D17: 3.46 | E17: Meet Expectation | F17: 3.46 | G17: Meet Expectation | H17: 3.86 | I17: Meet Expectation | J17: 3 | K17: Meet Expectation | L17: 3.1807692 | M17: Need to speed up the investigation and fixing process when issues arise. | N17: Meet Expectation | O17: 2.9371795 | P17: As we have many projects involved KPSG in AMFS, please do maintain the dedicated team for TM Revamp. Currently activities in other projects may impact in TM Revamp project, i.e. PureCloud Decommissioned impact in TM Revamp activities (huddle meeting) and deliverables (CRs). We believe each project has different urgency and separate budget which need to be considered not impacted each other. | Q17: Below Expectation | R17: 2.4272727 | S17: We concenrn about human resource, somehow we need extra effort time to make Change Request, Assesment Scope and issue. It takes long time to asses new Change Request because availibility human resources. | T17: Below Expectation | U17: 2x | V17: Pada periode Q2 mendapatkan hasil below expectation dan procurement sudah lakukan pemanggilan untuk menyampaikan evaluasi performance tersebut bersama sama dengan business user. Pada periode Q3, business user menyampaikan concern kembali dengan hasil below expectation, dan akan dilakukan pemanggilan kembali kepada KPSG. | W17: 3.5181818 | X17: PLEASE BE MORE PERFORMED BECAUSE OUR NEEDS IS SO FAST FOR STRATEGIC DELIVERY | Y17: MEET EXPECTATION | Z17: 3.0318182 | AA17: Diharapkan untuk tim project yang diassign apabila CR sudah di signoff agar availibility dari resource ready | AB17: MEET EXPECTATION | AC17: =IFERROR(VALUE('RESULT Q2'!E18),"N/A") -> 3.5393939 | AD17: =IFERROR('RESULT Q2'!G18,"-") -> 1. For AI Implementation, KPSG need to improve the delivery time, quality and PIC availability and backup PIC support 2. Another enhancement need to speed up with dedicated team | AE17: =IFERROR('RESULT Q2'!F18,"N/A") -> Meet Expectation | AF17: =B17&" - "&C17 -> KARYAPUTRA SURYAGEMILANG - TELEMARKETING REVAMP PROJECT | AG17: =IFERROR('RESULT Q2'!D18,"-") -> Nuril HUDHA
A18: 12 | B18: ARAH SEJAHTERA ABADI | C18: PERJANJIAN SEWA MENYEWA | D18: N/A | E18: N/A | F18: 3 | G18: Meet Expectation | H18: 3 | I18: Meet Expectation | J18: 3.35 | K18: Meet Expectation | L18: 2.8409091 | M18: Improve Resolution repair, for this year resolution fro problem dusty and project smell CCC impact project from another tenant behind CCC GF ( NOV 2024 until now still not yet solution ) | N18: Below Expectation | O18: 2.7727273 | P18: for improvment is Improve resolusi repair/corective device Building in tenant area | Q18: Below Expectation | R18: 2 | S18: adanya SLA atau KPI utuk review kuncit | T18: Below Expectation | U18: 3x | V18: Pada periode Q1, Q2, dan Q3, hasil penilaian evaluasinya cenderung turun karena dari pihak Kuningan City tidak bersedia dianggap sebagai vendor / supplier, yang bisa diberlakukan penilaian performance atas layanan yang diberikan. Dari sisi operasional, memberikan nilai below expectation karena pihak Kuncit dirasa kurang responsif dalam menanggapi keluhan. | W18: 2.9611111 | X18: KUNCIT SUPPORT FOR SPACE AMFS (GIVE MORE ADVANTAGE FREE CHARGE FOR 12), FOR THE REPAIR /SOLUTION NEED MORE IMPROVE TIME OR QUALITY | Y18: BELOW EXPECTATION | Z18: 2.9611111 | AA18: Improve quality service, specially for leakage, | AB18: BELOW EXPECTATION | AC18: =IFERROR(VALUE('RESULT Q2'!E23),"N/A") -> N/A | AD18: =IFERROR('RESULT Q2'!G23,"-") -> - | AE18: =IFERROR('RESULT Q2'!F23,"N/A") -> Tidak Dievaluasi Q2 | AF18: =B18&" - "&C18 -> ARAH SEJAHTERA ABADI - PERJANJIAN SEWA MENYEWA | AG18: =IFERROR('RESULT Q2'!D23,"-") -> ibnu.kumala@axa-mandiri.co.id
A19: 13 | B19: DELOITTE CONSULTING | C19: DATA PRIVACY TOOLS & PELATIHAN PERSONAL DATA PROTECTION (PDP) | D19: N/A | E19: N/A | F19: N/A | G19: N/A | H19: N/A | I19: N/A | J19: 3.2333333 | K19: Meet Expectation | L19: 2.9708333 | M19: They need to deepen their product knowledge so that they can be right on target in providing solutions. | N19: Below Expectation | O19: 2.8833333 | P19: Understand more about product feature knowledge so that vendors can explain accurately and convincingly when there is trouble or product limitations. | Q19: Below Expectation | R19: 3.1 | S19: More coordination with PIC Principal Product (Securiti.ai) to get information regarding product updates earlier. | T19: Meet Expectation | U19: 0x | V19: - | W19: 3.1166667 | X19: MORE COORDINATION WITH PIC PRINCIPAL PRODUCT (SECURITI.AI) TO GET INFORMATION REGARDING PRODUCT UPDATES EARLIER. | Y19: MEET EXPECTATION | Z19: 3.1636364 | AA19: Need more improvement regarding initiative to take mitigation/preventive action to prevent the problem from recurring/current issue. | AB19: MEET EXPECTATION | AC19: =IFERROR(VALUE('RESULT Q2'!E16),"N/A") -> 4.0636364 | AD19: =IFERROR('RESULT Q2'!G16,"-") -> In dealing with Security AI-related issues, Deloitte is occasionally unable to provide a resolution and therefore redirects the matter to the Security AI team. Furthermore, several system features are restricted, and these limitations were not clearly communicated at the outset. Consequently, this has created challenges in implementing system enhancements and aligning the system with the business requirements of Security AI users. | AE19: =IFERROR('RESULT Q2'!F16,"N/A") -> Exceed Expectation | AF19: =B19&" - "&C19 -> DELOITTE CONSULTING - DATA PRIVACY TOOLS & PELATIHAN PERSONAL DATA PROTECTION (PDP) | AG19: =IFERROR('RESULT Q2'!D16,"-") -> M. Andrian Patria Shaleh RIZAL
A20: 14 | B20: SUTRA MANAGEMENT CONSULTANCIES | C20: IMPLEMENTASI SAS IFRS17 | D20: N/A | E20: N/A | F20: N/A | G20: N/A | H20: N/A | I20: N/A | J20: N/A | K20: N/A | L20: 3.1866667 | M20: Sometimes the vendor must think out-of-the box meaning that they need to be "somehow creative enough" in expediting the problem-solution approaches to any issues being raised by us as customers in the fields of both IT and Finance/Actuary. They seems to play "by the book" instead of proposing the new ideas and thoughts flexibel enough to be implemented as long as not crossing the compliance issues. Those kind ideas that can help us to have more effective and productive outcomes in the very challenging timeline. | N20: Meet Expectation | O20: 3.6733333 | P20: In overall is above the "Good Criteria" except when starting to develop the infrastructure in the beginning because the development team of this vendor is not in Jakarta but instead in India that added extra challenges for us to communicate (in English) and coordinate (long distance) | Q20: Meet Expectation | R20: 3.5166667 | S20: I think we need to be fair that the PSAK117 Methodology is the new thing that even for the vendor to execute in the CSM Engine needs to know some critical particular requirements that business users expect for CSM to deliver. Therefore, CSM Engine needs to be customized, and this takes time from the vendor to adjust/modify. My suggestion for the vendor is to always provide a stand-by expertise in the field of IFRS17 Methodoly, and he/she is able to explain clearly to users how these things work in the CSM System, and how users should provide required items in our existing data input system. Mutual understanding is the key; system modification is easy to implement; and expertise people from the vendor are always stand by | T20: Meet Expectation | U20: 0x | V20: - | W20: 3.8666667 | X20: N/A | Y20: MEET EXPECTATION | Z20: 3.6833333 | AA20: Local vendor Sutra is affiliated with SAS Technology which is known as more expensive system compared to other vendors during the Vendor Bidding Process. However, SAS Technology System has been used in few well-known insurance companies in Indonesia, so it is easier to get the review and information; mostly positive. | AB20: MEET EXPECTATION | AC20: =IFERROR(VALUE('RESULT Q2'!E14),"N/A") -> 3.3333333 | AD20: =IFERROR('RESULT Q2'!G14,"-") -> no feedback | AE20: =IFERROR('RESULT Q2'!F14,"N/A") -> Meet Expectation | AF20: =B20&" - "&C20 -> SUTRA MANAGEMENT CONSULTANCIES - IMPLEMENTASI SAS IFRS17 | AG20: =IFERROR('RESULT Q2'!D14,"-") -> Tatang SUTIAMAN
A21: 15 | B21: TMF INDONESIA | C21: PAYROLL | L21: N/A | M21: N/A | N21: N/A | O21: N/A | P21: N/A | Q21: N/A | R21: N/A | S21: N/A | T21: N/A | U21: 3 | V21: BETTER COORDINATION THAN 2025, REPORTS ARE ALWAYS REVIEWED BY RELATED MANAGER BEFORE SUBMIT TO AMFS PIC. | Z21: 3 | AA21: Always check and recheck the task in internal PIC TMF before send the report to AMFS PIC | AB21: MEET EXPECTATION | AC21: =IFERROR(VALUE('RESULT Q2'!E17),"N/A") -> 3 | AD21: =IFERROR('RESULT Q2'!G17,"-") -> - | AE21: =IFERROR('RESULT Q2'!F17,"N/A") -> Meet Expectation | AF21: =B21&" - "&C21 -> TMF INDONESIA - PAYROLL | AG21: =IFERROR('RESULT Q2'!D17,"-") -> Enung HARYATI
A22: 16 | B22: REYCOM DOCUMENT SOLUTION | C22: PRINTING & DMC | L22: N/A | M22: N/A | N22: N/A | O22: N/A | P22: N/A | Q22: N/A | R22: N/A | S22: N/A | T22: N/A | U22: 3.5416667 | V22: PLEASE BE MORE PERFORMED BECAUSE OUR NEEDS IS SO FAST FOR STRATEGIC DELIVERY | Z22: 4.7666667 | AA22: More inovation for 2026 | AB22: EXCEED EXPECTATION | AC22: =IFERROR(VALUE('RESULT Q2'!E15),"N/A") -> 4.3 | AD22: =IFERROR('RESULT Q2'!G15,"-") -> Improvements to their latest Technology to support process at AXA | AE22: =IFERROR('RESULT Q2'!F15,"N/A") -> Exceed Expectation | AF22: =B22&" - "&C22 -> REYCOM DOCUMENT SOLUTION - PRINTING & DMC | AG22: =IFERROR('RESULT Q2'!D15,"-") -> Yulia KURNIATI
A23: 17 | B23: FPT METRODATA INDONESIA | C23: PENETRATION TEST | Z23: 3 | AA23: No need improvement | AB23: MEET EXPECTATION | AC23: =IFERROR(VALUE('RESULT Q2'!E4),"N/A") -> 4 | AD23: =IFERROR('RESULT Q2'!G4,"-") -> - | AE23: =IFERROR('RESULT Q2'!F4,"N/A") -> Exceed Expectation | AF23: =B23&" - "&C23 -> FPT METRODATA INDONESIA - PENETRATION TEST | AG23: =IFERROR('RESULT Q2'!D4,"-") -> Fauzi ARYANTO
A24: 18 | B24: IPROTEKSI TELEMATIKA | C24: PENETRATION TEST | Z24: 4 | AA24: no need improvement | AB24: MEET EXPECTATION | AC24: =IFERROR(VALUE('RESULT Q2'!E3),"N/A") -> 4 | AD24: =IFERROR('RESULT Q2'!G3,"-") -> - | AE24: =IFERROR('RESULT Q2'!F3,"N/A") -> Exceed Expectation | AF24: =B24&" - "&C24 -> IPROTEKSI TELEMATIKA - PENETRATION TEST | AG24: =IFERROR('RESULT Q2'!D3,"-") -> Fauzi ARYANTO
A25: 19 | B25: ITSEC ASIA | C25: PENETRATION TEST | Z25: 3 | AA25: Currently no need improvement | AB25: MEET EXPECTATION | AC25: =IFERROR(VALUE('RESULT Q2'!E2),"N/A") -> 3 | AD25: =IFERROR('RESULT Q2'!G2,"-") -> - | AE25: =IFERROR('RESULT Q2'!F2,"N/A") -> Meet Expectation | AF25: =B25&" - "&C25 -> ITSEC ASIA - PENETRATION TEST | AG25: =IFERROR('RESULT Q2'!D2,"-") -> Fauzi ARYANTO
A26: 20 | B26: Karyaputra Suryagemilang | C26: Purecloud Decommisioning | D26: N/A | E26: - | F26: N/A | G26: - | H26: N/A | I26: - | J26: N/A | K26: - | L26: N/A | M26: - | N26: N/A | O26: N/A | P26: - | Q26: N/A | R26: N/A | S26: - | T26: N/A | U26: N/A | V26: - | W26: N/A | X26: N/A | Y26: N/A | Z26: N/A | AA26: - | AB26: N/A | AC26: =IFERROR(VALUE('RESULT Q2'!E20),"N/A") -> 3.4458333 | AD26: =IFERROR('RESULT Q2'!G20,"-") -> 1. KPSG-ARSI Perspective (The approach applied is still limited to best practices without considering the scenarios occurring in AMFS). 2. Requirement Gap (There is a significant requirement gap due to missed requirements, caused by insufficient exploration of user needs and requirements) 3. Frequent Manpower (MP) and PIC Changes (Manpower changes occur quite frequently, while the implementation team is no longer on-site. The PIC from KPSG also changes often. It is requested that a dedicated PIC be provided for IT Support as well as a dedicated Project Manager) 4. Deployment Issues (Each deployment consistently results in new issues that impact areas outside the deployment scope. This indicates a lack of proper health checks after deployment). 5. Deployment Communication (Communication regarding deployment plans is still lacking, particularly in obtaining approval from business users. This matter has already been communicated by AMFS to the KPSG team). 6. Contact Center Experience (The team’s experience in contact center operations, especially inbound, remains limited). 7. Change Requests (CR) and Production Issues (Many CRs and production issues are delivered based on targets determined unilaterally by KPSG). 8. User Guide and Feature Socialization. (The User Guide is not well maintained. When new features are introduced, documentation should be updated immediately, socialized to users, and the latest User Guide shared to ensure optimal usage) | AE26: =IFERROR('RESULT Q2'!F20,"N/A") -> Meet Expectation | AF26: =B26&" - "&C26 -> Karyaputra Suryagemilang - Purecloud Decommisioning | AG26: =IFERROR('RESULT Q2'!D20,"-") -> Noviani MARBUN
A27: 21 | B27: Mitra Integrasi Informatika | C27: Purecloud Decommisioning | D27: N/A | E27: - | F27: N/A | G27: - | H27: N/A | I27: - | J27: N/A | K27: - | L27: N/A | M27: - | N27: N/A | O27: N/A | P27: - | Q27: N/A | R27: N/A | S27: - | T27: N/A | U27: N/A | V27: - | W27: N/A | X27: N/A | Y27: N/A | Z27: N/A | AA27: - | AB27: N/A | AC27: =IFERROR(VALUE('RESULT Q2'!E21),"N/A") -> 3.8833333 | AD27: =IFERROR('RESULT Q2'!G21,"-") -> 1) Training Process During the training sessions, it is expected that explanations are delivered in detail and step by step. When participants are conducting hands-on activities, they should be properly provided with guidance and direct support. This is important to avoid unnecessary questions that could otherwise be answered clearly, ensuring that participants can immediately understand the changes and new features introduced. 2) “Baby Sitting” Phase In the “baby sitting” phase, the MII team was expected to be present full day on-site at AMFS for two weeks. However, in practice, the team did not consistently attend and only joined full day after being specifically requested. As a result, the actual presence was only around five days instead of the full two weeks as originally required. | AE27: =IFERROR('RESULT Q2'!F21,"N/A") -> Meet Expectation | AF27: =B27&" - "&C27 -> Mitra Integrasi Informatika - Purecloud Decommisioning | AG27: =IFERROR('RESULT Q2'!D21,"-") -> Noviani MARBUN
A28: 22 | B28: ESHAEL Indonesia | C28: Talent Assesment | D28: N/A | E28: - | F28: N/A | G28: - | H28: N/A | I28: - | J28: N/A | K28: - | L28: N/A | M28: - | N28: N/A | O28: N/A | P28: - | Q28: N/A | R28: N/A | S28: - | T28: N/A | U28: N/A | V28: - | W28: N/A | X28: N/A | Y28: N/A | Z28: N/A | AA28: - | AB28: N/A | AC28: =IFERROR(VALUE('RESULT Q2'!E22),"N/A") -> 4.6083333 | AD28: =IFERROR('RESULT Q2'!G22,"-") -> N/A | AE28: =IFERROR('RESULT Q2'!F22,"N/A") -> Exceed Expectation | AF28: =B28&" - "&C28 -> ESHAEL Indonesia - Talent Assesment | AG28: =IFERROR('RESULT Q2'!D22,"-") -> I Gusti Ayu Mira SETYAWARDHANIE

Sheet SUMMARY Q2 2026
A1: CRITICAL SUPPLIER PERFORMANCE REVIEW — SUMMARY Q2 2026
A2: Periode Review | B2: Q2 2026
A3: Jumlah Vendor Dievaluasi | B3: =COUNTA('RESULT Q2'!B2:B22) -> 21
A4: Total Vendor Kritis (Master List) - Input Manual | B4: 22
A5: % Vendor Dievaluasi | B5: =B3/B4 -> 0.95454545
A6: Jumlah "Meet / Exceed / Exceptional" | B6: =SUMPRODUCT(--(('RESULT Q2'!F2:F23<>"Below Expectation")*('RESULT Q2'!F2:F23<>"Unsatisfactory")*('RESULT Q2'!F2:F23<>"Tidak Dievaluasi Q2"))) -> 20
A7: Jumlah "Under Performance" (Below Expectation/Unsatisfactory) | B7: =COUNTIF('RESULT Q2'!F2:F23,"Below Expectation")+COUNTIF('RESULT Q2'!F2:F23,"Unsatisfactory") -> 1
A8: Jumlah Vendor Tidak Dievaluasi Q2 | B8: =COUNTIF('RESULT Q2'!F2:F23,"Tidak Dievaluasi Q2") -> 1
A9: Vendor Critical Below Expectation | B9: =_xlfn.TEXTJOIN(", ",TRUE(),'RESULT Q2'!I2:I23) -> Target Sukses Sinergi - Email Marketing Automation
A10: Vendor Baru Q2 2026 (belum ada histori) | B10: Karyaputra Suryagemilang - Purecloud Decommisioning; Mitra Integrasi Informatika - Purecloud Decommisioning; ESHAEL Indonesia - Talent Assesment

Sheet RESULT Q2
A1: No | B1: Vendor | C1: Service | D1: PIC (User) | E1: Total Score | F1: Status | G1: Remarks | H1: Catatan Data | I1: Helper: Below/Unsatisfactory Name
A2: 1 | B2: Itsec Asia | C2: Penetration Testing | D2: Fauzi ARYANTO | E2: ='Q2 ITSEC'!B20 -> 3 | F2: ='Q2 ITSEC'!B21 -> Meet Expectation | G2: ='Q2 ITSEC'!B32 -> - | I2: =IF(OR(F2="Below Expectation",F2="Unsatisfactory"),B2&" - "&C2,"")
A3: 2 | B3: Iproteksi Telematika | C3: Penetration Testing | D3: Fauzi ARYANTO | E3: ='Q2 IPROTEKSI'!B20 -> 4 | F3: ='Q2 IPROTEKSI'!B21 -> Exceed Expectation | G3: ='Q2 IPROTEKSI'!B32 -> - | I3: =IF(OR(F3="Below Expectation",F3="Unsatisfactory"),B3&" - "&C3,"")
A4: 3 | B4: FPT Metrodata | C4: Penetration Testing | D4: Fauzi ARYANTO | E4: ='Q2 FPT'!B20 -> 4 | F4: ='Q2 FPT'!B21 -> Exceed Expectation | G4: ='Q2 FPT'!B32 -> - | I4: =IF(OR(F4="Below Expectation",F4="Unsatisfactory"),B4&" - "&C4,"")
A5: 4 | B5: Satria Antaran Prima | C5: Mailing Room | D5: Ibnu KUMALA | E5: ='Q2 SAP-Mailing'!B25 -> 3.04375 | F5: ='Q2 SAP-Mailing'!B26 -> Meet Expectation | G5: ='Q2 SAP-Mailing'!B37 -> improve inisiatsis | I5: =IF(OR(F5="Below Expectation",F5="Unsatisfactory"),B5&" - "&C5,"")
A6: 5 | B6: Informasi Teknologi Indonesia - SMS Broadcast | D6: Fifin SARINURLITA | E6: ='Q2 JATIS'!B29 -> 3 | F6: ='Q2 JATIS'!B30 -> Meet Expectation | G6: ='Q2 JATIS'!B41 -> So far, Jatis Vendor has provided good service. Their response time is fast, and they are able to provide effective solutions whenever issues arise | I6: =IF(OR(F6="Below Expectation",F6="Unsatisfactory"),B6&" - "&C6,"")
A7: 6 | B7: Satria Antaran Prima | C7: Courier Service | D7: Fifin SARINURLITA, Novia Laras SANTI | E7: ='Q2 SAP-Courier'!B33 -> 3.2383333 | F7: ='Q2 SAP-Courier'!B34 -> Meet Expectation | G7: ='Q2 SAP-Courier'!B47&" | "&'Q2 SAP-Courier'!B48 -> SAP has shown improvement in terms of reporting and provides a fast response whenever issues arise. | 1. untuk detail status pengiriman dokumen/barang harus diberikan keterangan penerima dengan lengkap dan jelas; 2. Maks. SLA pengiriman harus memenuhi sesuai dengan yang ditetapkan yaitu <5% not meet SLA; 3. Invoice biaya pengiriman dikirimkan ke user yang sesuai dan dikirimkan tidak melebihi periode yang ditetapkan. 4. Report Stock sesuai dengan real stock di warehouse. | H7: Skor rata-rata 2 business user (kasus normal, multiple raters untuk vendor/service yang sama). | I7: =IF(OR(F7="Below Expectation",F7="Unsatisfactory"),B7&" - "&C7,"")
A8: 7 | B8: Multifiling Mitra Indonesia | C8: Record Management Service | D8: Ibnu KUMALA | E8: ='Q2 MMI'!B29 -> 3 | F8: ='Q2 MMI'!B30 -> Meet Expectation | G8: ='Q2 MMI'!B41 -> .. | I8: =IF(OR(F8="Below Expectation",F8="Unsatisfactory"),B8&" - "&C8,"")
A9: 8 | B9: Indosat | C9: Layanan PBX berbasiskan cloud dengan Teknologi SIP Trunk | D9: Nuril HUDHA | E9: ='Q2 INDOSAT'!B36 -> 3.4394737 | F9: ='Q2 INDOSAT'!B37 -> Meet Expectation | G9: ='Q2 INDOSAT'!B48 -> Vendor performance is generally acceptable and aligns with the expected level of service. While the engagement has been positive overall, improvements are needed in feature enhancement, dashboard capabilities, and the regularity of report updates. Better preparation in deployment and timely reporting would help increase the overall value and effectiveness of the service. | I9: =IF(OR(F9="Below Expectation",F9="Unsatisfactory"),B9&" - "&C9,"")
A10: 9 | B10: Ciptadra Softindo | C10: Pemeliharaan Axits & DMTM | D10: Raninta MAHARDI | E10: ='Q2 CIPTADRA'!B32 -> 4.3 | F10: ='Q2 CIPTADRA'!B33 -> Exceed Expectation | G10: ='Q2 CIPTADRA'!B44 -> Ciptadra selalu fast response ketika ada incident yang terjadi di DMTM | I10: =IF(OR(F10="Below Expectation",F10="Unsatisfactory"),B10&" - "&C10,"")
A11: 10 | B11: Target Sukses Sinergi | C11: Email Marketing Automation | D11: Bella Friska DEPARI | E11: ='Q2 MTARGET'!B23 -> 2.9416667 | F11: ='Q2 MTARGET'!B24 -> Below Expectation | G11: ='Q2 MTARGET'!B35 -> Secara keseluruhan, MTarget telah memberikan dukungan yang baik dalam operasional email campaign dan responsif dalam menangani kebutuhan maupun isu yang muncul. Namun, insiden kesalahan pengiriman email yang terjadi menunjukkan perlunya penguatan pada proses deployment, pengujian, serta validasi sebelum implementasi ke production. Ke depannya, kami berharap MTarget dapat memperkuat proses change management, quality assurance, dan kontrol terhadap segmentasi serta pengiriman email untuk meminimalkan risiko terjadinya insiden serupa. | I11: =IF(OR(F11="Below Expectation",F11="Unsatisfactory"),B11&" - "&C11,"") -> Target Sukses Sinergi - Email Marketing Automation
A12: 11 | B12: Inmotion Inovasi Teknologi | C12: Jasa Aplikasi Chatbot dan Live Chat | D12: Djoko DJOKO | E12: ='Q2 INMOTION'!B54 -> 4 | F12: ='Q2 INMOTION'!B55 -> Exceed Expectation | G12: ='Q2 INMOTION'!B66 -> Tetap up to date dan helpful | I12: =IF(OR(F12="Below Expectation",F12="Unsatisfactory"),B12&" - "&C12,"")
A13: 12 | B13: Mitra Integrasi Informatika | C13: SFDC Maintenance | D13: Chandra Nugraha PUTRA | E13: ='Q2 MII-SFDC'!B30 -> 4.7487179 | F13: ='Q2 MII-SFDC'!B31 -> Exceed Expectation | G13: ='Q2 MII-SFDC'!B42 -> Respons terhadap issue maupun kebutuhan sudah cukup baik dan cepat. Support on-site juga sangat membantu dan responsif. Ke depannya, mungkin dapat lebih rutin memberikan update terkait progress kendala atau perbaikan yang sedang dilakukan, sehingga pihak terkait dapat mengetahui status terbaru dan lebih cepat menentukan langkah selanjutnya. | I13: =IF(OR(F13="Below Expectation",F13="Unsatisfactory"),B13&" - "&C13,"")
A14: 13 | B14: Sutra Management Consultancies | C14: Implementasi SAS IFRS17 | D14: Tatang SUTIAMAN | E14: ='Q2 SUTRA'!B38 -> 3.3333333 | F14: ='Q2 SUTRA'!B39 -> Meet Expectation | G14: ='Q2 SUTRA'!B50 -> no feedback | I14: =IF(OR(F14="Below Expectation",F14="Unsatisfactory"),B14&" - "&C14,"")
A15: 14 | B15: Reycom Document Solution | C15: Printing & Data Management Center | D15: Yulia KURNIATI | E15: ='Q2 RDS-Printing'!B33 -> 4.3 | F15: ='Q2 RDS-Printing'!B34 -> Exceed Expectation | G15: ='Q2 RDS-Printing'!B45 -> Improvements to their latest Technology to support process at AXA | H15: Vendor submit 2x; menggunakan submission terakhir (lebih lengkap). | I15: =IF(OR(F15="Below Expectation",F15="Unsatisfactory"),B15&" - "&C15,"")
A16: 15 | B16: Deloitte Consulting | C16: Data Privacy & Pelatihan Personal Data Protection (PDP) | D16: M. Andrian Patria Shaleh RIZAL | E16: ='Q2 DELOITTE'!B28 -> 4.0636364 | F16: ='Q2 DELOITTE'!B29 -> Exceed Expectation | G16: ='Q2 DELOITTE'!B40 -> In dealing with Security AI-related issues, Deloitte is occasionally unable to provide a resolution and therefore redirects the matter to the Security AI team. Furthermore, several system features are restricted, and these limitations were not clearly communicated at the outset. Consequently, this has created challenges in implementing system enhancements and aligning the system with the business requirements of Security AI users. | I16: =IF(OR(F16="Below Expectation",F16="Unsatisfactory"),B16&" - "&C16,"")
A17: 16 | B17: TMF Indonesia | C17: Payroll | D17: Enung HARYATI | E17: ='Q2 TMF'!B23 -> 3 | F17: ='Q2 TMF'!B24 -> Meet Expectation | G17: ='Q2 TMF'!B35 -> - | I17: =IF(OR(F17="Below Expectation",F17="Unsatisfactory"),B17&" - "&C17,"")
A18: 17 | B18: Karya Putra Surya Gemilang | C18: Telemarketing Revamp Project | D18: Nuril HUDHA | E18: ='Q2 KPSG-TM'!B28 -> 3.5393939 | F18: ='Q2 KPSG-TM'!B29 -> Meet Expectation | G18: ='Q2 KPSG-TM'!B40 -> 1. For AI Implementation, KPSG need to improve the delivery time, quality and PIC availability and backup PIC support 2. Another enhancement need to speed up with dedicated team | I18: =IF(OR(F18="Below Expectation",F18="Unsatisfactory"),B18&" - "&C18,"")
A19: 18 | B19: Wiz Technology | C19: Voice Bot Reminder Call | D19: Ravika OKTAVIANI | E19: ='Q2 WIZ'!B25 -> 3.0875 | F19: ='Q2 WIZ'!B26 -> Meet Expectation | G19: ='Q2 WIZ'!B37 -> To ensure a smooth process, we need to move faster and maintain effective communication | I19: =IF(OR(F19="Below Expectation",F19="Unsatisfactory"),B19&" - "&C19,"")
A20: 19 | B20: Karyaputra Suryagemilang | C20: Purecloud Decommisioning | D20: Noviani MARBUN | E20: ='Q2 KPSG-ARSI'!B34 -> 3.4458333 | F20: ='Q2 KPSG-ARSI'!B35 -> Meet Expectation | G20: ='Q2 KPSG-ARSI'!B46 -> 1. KPSG-ARSI Perspective (The approach applied is still limited to best practices without considering the scenarios occurring in AMFS). 2. Requirement Gap (There is a significant requirement gap due to missed requirements, caused by insufficient exploration of user needs and requirements) 3. Frequent Manpower (MP) and PIC Changes (Manpower changes occur quite frequently, while the implementation team is no longer on-site. The PIC from KPSG also changes often. It is requested that a dedicated PIC be provided for IT Support as well as a dedicated Project Manager) 4. Deployment Issues (Each deployment consistently results in new issues that impact areas outside the deployment scope. This indicates a lack of proper health checks after deployment). 5. Deployment Communication (Communication regarding deployment plans is still lacking, particularly in obtaining approval from business users. This matter has already been communicated by AMFS to the KPSG team). 6. Contact Center Experience (The team’s experience in contact center operations, especially inbound, remains limited). 7. Change Requests (CR) and Production Issues (Many CRs and production issues are delivered based on targets determined unilaterally by KPSG). 8. User Guide and Feature Socialization. (The User Guide is not well maintained. When new features are introduced, documentation should be updated immediately, socialized to users, and the latest User Guide shared to ensure optimal usage) | H20: Vendor/proyek baru; belum ada histori kuartal sebelumnya. Klasifikasi Quality/Timeline pada pertanyaan custom memakai heuristik kata kunci — mohon di-review SRM. | I20: =IF(OR(F20="Below Expectation",F20="Unsatisfactory"),B20&" - "&C20,"")
A21: 20 | B21: Mitra Integrasi Informatika | C21: Purecloud Decommisioning | D21: Noviani MARBUN | E21: ='Q2 MII-Purecloud'!B30 -> 3.8833333 | F21: ='Q2 MII-Purecloud'!B31 -> Meet Expectation | G21: ='Q2 MII-Purecloud'!B42 -> 1) Training Process During the training sessions, it is expected that explanations are delivered in detail and step by step. When participants are conducting hands-on activities, they should be properly provided with guidance and direct support. This is important to avoid unnecessary questions that could otherwise be answered clearly, ensuring that participants can immediately understand the changes and new features introduced. 2) “Baby Sitting” Phase In the “baby sitting” phase, the MII team was expected to be present full day on-site at AMFS for two weeks. However, in practice, the team did not consistently attend and only joined full day after being specifically requested. As a result, the actual presence was only around five days instead of the full two weeks as originally required. | H21: Vendor/proyek baru; belum ada histori kuartal sebelumnya. Klasifikasi Quality/Timeline pada pertanyaan custom memakai heuristik kata kunci — mohon di-review SRM. | I21: =IF(OR(F21="Below Expectation",F21="Unsatisfactory"),B21&" - "&C21,"")
A22: 21 | B22: ESHAEL Indonesia | C22: Talent Assesment | D22: I Gusti Ayu Mira SETYAWARDHANIE | E22: ='Q2 ESHAEL'!B29 -> 4.6083333 | F22: ='Q2 ESHAEL'!B30 -> Exceed Expectation | G22: ='Q2 ESHAEL'!B41 -> N/A | H22: Vendor/proyek baru; belum ada histori kuartal sebelumnya. Klasifikasi Quality/Timeline pada pertanyaan custom memakai heuristik kata kunci — mohon di-review SRM. | I22: =IF(OR(F22="Below Expectation",F22="Unsatisfactory"),B22&" - "&C22,"")
A23: 22 | B23: Arah Sejahtera Abadi | C23: Perjanjian Sewa Menyewa | D23: ibnu.kumala@axa-mandiri.co.id | E23: N/A | F23: Tidak Dievaluasi Q2 | G23: - | H23: Vendor tidak mengisi assessment pada periode Q2 2026. | I23: =IF(OR(F23="Below Expectation",F23="Unsatisfactory"),B23&" - "&C23,"")

Sheet Q2 ITSEC
A1: HASIL REVIEW VENDOR — Q2 2026
A2: Vendor | B2: Itsec Asia
A3: Service | B3: Penetration Testing
A4: PIC (Business User) | B4: Fauzi ARYANTO
A6: No | B6: Dimensi | C6: Pertanyaan | D6: Skor
A7: 1 | B7: Quality | C7: ='RAW DATA Q2 - 1'!ER$1 -> How would you rate the Technical services that is used to penetrate the application which includes: 1. Technical Specification Design. 2. Hardware and capacity sizing for concurrent requests 3. Functi2 | D7: ='RAW DATA Q2 - 1'!ER10 -> 3
A8: 2 | B8: Quality | C8: ='RAW DATA Q2 - 1'!ES$1 -> How would you rate the after sales support capability and methodology?2 | D8: ='RAW DATA Q2 - 1'!ES10 -> 3
A9: 3 | B9: Quality | C9: ='RAW DATA Q2 - 1'!ET$1 -> How would you rate the availability of documentation for product (user manual, troubleshoot document, setup document, etc)?1 | D9: ='RAW DATA Q2 - 1'!ET10 -> 3
A10: 4 | B10: Timeline | C10: ='RAW DATA Q2 - 1'!EU$1 -> How would you rate the supplier's timeliness in delivering goods/services compared to the agreed-upon timeline? | D10: ='RAW DATA Q2 - 1'!EU10 -> 3
A11: 5 | B11: Timeline | C11: ='RAW DATA Q2 - 1'!EV$1 -> How would you rate the supplier's timeliness in sending reports to you? | D11: ='RAW DATA Q2 - 1'!EV10 -> 3
A12: 6 | B12: Timeline | C12: ='RAW DATA Q2 - 1'!EW$1 -> How would you rate the supplier's speed ​​of administrative completion, including completion of contracts draft? | D12: ='RAW DATA Q2 - 1'!EW10 -> 3
A13: 7 | B13: Relationship | C13: ='RAW DATA Q2 - 1'!FM$1 -> How would you rate the supplier's communication with you? | D13: ='RAW DATA Q2 - 1'!FM10 -> 3
A14: 8 | B14: Relationship | C14: ='RAW DATA Q2 - 1'!FN$1 -> How would you rate the supplier's PIC's availability to be contacted when needed? | D14: ='RAW DATA Q2 - 1'!FN10 -> 3
A15: 9 | B15: Relationship | C15: ='RAW DATA Q2 - 1'!FO$1 -> How would you rate the supplier's response speed to you when there are issues? | D15: ='RAW DATA Q2 - 1'!FO10 -> 3
