Workbook

Sheet README
A1: CRITICAL SUPPLIER PERFORMANCE REVIEW — REVAMPED WORKBOOK
A2: Remediation & Restructuring Q1 2026 → Template Reusable untuk Q2 2026
A4: 1. APA YANG BERUBAH DARI FILE ASLI
A5: • 18 sheet per-supplier (ITSEC, IPROTEKSI, dst) dengan angka HARDCODE dikonsolidasikan menjadi 1 sheet SCORE CALC — semua nilai sekarang formula, ditarik LANGSUNG dari RAW DATA, tidak ada lagi copy-paste manual.
A6: • Sheet CONFIG baru ditambahkan: berisi mapping kolom (Quality/Timeline/Relationship) per supplier ke RAW DATA. Ini yang membuat file REUSABLE — untuk Q2, cukup update kolom 'Raw Sheet Name' di CONFIG dan tempel data baru, seluruh perhitungan otomatis mengikuti.
A7: • Sheet RESULT dirombak: Total Score, Status, Remarks, dan DD Result (by User) sekarang 100% formula (live link ke raw data). Kolom 'Assessment Result (by SRM)' dan 'Repetition of Below Expectation' tetap manual input (kuning) karena butuh judgement SRM, bukan hasil kalkulasi.
A8: • Sheet SUMMARY diperbaiki: '% Vendor Dievaluasi' sebelumnya menampilkan angka mentah (1) alih-alih persentase — sekarang benar (0%-100%) dan berbasis formula, bukan hitung manual.
A9: • Sheet HISTORICAL: kolom skor Q1 2026 sekarang live-link ke RESULT (bukan angka mati), dan status (Meet/Exceed/dst) memakai formula ambang batas yang SAMA dengan kolom tahun-tahun sebelumnya (sebelumnya kolom Q1 2026 di-ketik manual, tidak konsisten dengan formula tahun lalu).
A10: • Sheet 'Sheet1' (draft yang tidak terpakai, cuma 1 baris) dihapus.
A12: 2. BUG YANG DITEMUKAN & DIPERBAIKI (PENTING)
A13: Saat formula lama diganti dengan link otomatis ke raw data, ditemukan 3 kesalahan formula di file asli:
A14: a) Satria Antaran Prima – Mailing Room: formula Timeline ("=AVERAGE(I3:P3)*35%") salah rentang — ikut merata-ratakan kolom Quality & hasil weighted Quality (M3) alih-alih hanya kolom Timeline (N:P). Total Score resmi 3.063272 → seharusnya 3.404167. Status TETAP 'Meet Expectation', tidak berubah.
... A58: 5) Untuk detail jawaban per pertanyaan suatu vendor, buka sheet 'Q2 [nama vendor]' (contoh: 'Q2 ITSEC').

Sheet DASHBOARD
A1: DASHBOARD — CRITICAL SUPPLIER PERFORMANCE REVIEW
A3: 🔍 Cari Vendor: | C3: ITSEC ASIA - PENETRATION TEST | J3: MatchRow
A4: (pilih dari dropdown, atau ketik sebagian nama) | J4: =IFERROR(MATCH($C$3,HISTORICAL!$R$4:$R$25,0)+3,"") -> 22
A6: Vendor | B6: Service | C6: PIC Saat Ini | D6: Skor Q2 2026 | E6: Status Q2 2026 | F6: Skor Q1 2026 | G6: Tren vs Q1
A7: =IF($J$4="","",INDEX(HISTORICAL!B:B,$J$4)) -> ITSEC ASIA | B7: =IF($J$4="","",INDEX(HISTORICAL!C:C,$J$4)) -> PENETRATION TEST | C7: =IF($J$4="","",INDEX(HISTORICAL!O:O,$J$4)) -> Fauzi ARYANTO | D7: =IF($J$4="","",INDEX(HISTORICAL!M:M,$J$4)) -> 3 | E7: =IF($J$4="","",INDEX(HISTORICAL!N:N,$J$4)) -> Meet Expectation | F7: =IF($J$4="","",INDEX(HISTORICAL!L:L,$J$4)) -> 3 | G7: =IF($J$4="","",IF(OR(F7="",D7=""),"n/a",IF(D7>F7,"▲ Naik "&TEXT(D7-F7,"0.00"),IF(D7<F7,"▼ Turun "&TEXT(F7-D7,"0.00"),"— Stabil")))) -> — Stabil
A10: TREN SKOR PER KUARTAL
A11: 2024 Q1 | B11: 2024 Q2 | C11: 2024 Q3 | D11: 2024 Q4 | E11: 2025 Q1 | F11: 2025 Q2 | G11: 2025 Q3 | H11: 2025 Q4 | I11: 2026 Q1 | J11: 2026 Q2
A12: =IF($J$4="","",IF(OR(INDEX(HISTORICAL!D:D,$J$4)="N/A",INDEX(HISTORICAL!D:D,$J$4)=0),"-",INDEX(HISTORICAL!D:D,$J$4))) -> - | B12: =IF($J$4="","",IF(OR(INDEX(HISTORICAL!E:E,$J$4)="N/A",INDEX(HISTORICAL!E:E,$J$4)=0),"-",INDEX(HISTORICAL!E:E,$J$4))) -> - | C12: =IF($J$4="","",IF(OR(INDEX(HISTORICAL!F:F,$J$4)="N/A",INDEX(HISTORICAL!F:F,$J$4)=0),"-",INDEX(HISTORICAL!F:F,$J$4))) -> - | D12: =IF($J$4="","",IF(OR(INDEX(HISTORICAL!G:G,$J$4)="N/A",INDEX(HISTORICAL!G:G,$J$4)=0),"-",INDEX(HISTORICAL!G:G,$J$4))) -> - | E12: =IF($J$4="","",IF(OR(INDEX(HISTORICAL!H:H,$J$4)="N/A",INDEX(HISTORICAL!H:H,$J$4)=0),"-",INDEX(HISTORICAL!H:H,$J$4))) -> - | F12: =IF($J$4="","",IF(OR(INDEX(HISTORICAL!I:I,$J$4)="N/A",INDEX(HISTORICAL!I:I,$J$4)=0),"-",INDEX(HISTORICAL!I:I,$J$4))) -> - | G12: =IF($J$4="","",IF(OR(INDEX(HISTORICAL!J:J,$J$4)="N/A",INDEX(HISTORICAL!J:J,$J$4)=0),"-",INDEX(HISTORICAL!J:J,$J$4))) -> - | H12: =IF($J$4="","",IF(OR(INDEX(HISTORICAL!K:K,$J$4)="N/A",INDEX(HISTORICAL!K:K,$J$4)=0),"-",INDEX(HISTORICAL!K:K,$J$4))) -> - | I12: =IF($J$4="","",IF(OR(INDEX(HISTORICAL!L:L,$J$4)="N/A",INDEX(HISTORICAL!L:L,$J$4)=0),"-",INDEX(HISTORICAL!L:L,$J$4))) -> 3 | J12: =IF($J$4="","",IF(OR(INDEX(HISTORICAL!M:M,$J$4)="N/A",INDEX(HISTORICAL!M:M,$J$4)=0),"-",INDEX(HISTORICAL!M:M,$J$4))) -> 3
A19: (data pendukung grafik)
A20: 2024 Q1 | B20: =IFERROR(IF(A12="-",NA(),VALUE(A12)),NA()) -> #N/A
A21: 2024 Q2 | B21: =IFERROR(IF(B12="-",NA(),VALUE(B12)),NA()) -> #N/A
A22: 2024 Q3 | B22: =IFERROR(IF(C12="-",NA(),VALUE(C12)),NA()) -> #N/A
A23: 2024 Q4 | B23: =IFERROR(IF(D12="-",NA(),VALUE(D12)),NA()) -> #N/A
A24: 2025 Q1 | B24: =IFERROR(IF(E12="-",NA(),VALUE(E12)),NA()) -> #N/A
A25: 2025 Q2 | B25: =IFERROR(IF(F12="-",NA(),VALUE(F12)),NA()) -> #N/A
A26: 2025 Q3 | B26: =IFERROR(IF(G12="-",NA(),VALUE(G12)),NA()) -> #N/A
A27: 2025 Q4 | B27: =IFERROR(IF(H12="-",NA(),VALUE(H12)),NA()) -> #N/A
A28: REMARKS / FEEDBACK
A29: Q1 2026: | B29: =IF($J$4="","",INDEX(HISTORICAL!P:P,$J$4)) -> Currently no need improvement
A30: Q2 2026: | B30: =IF($J$4="","",INDEX(HISTORICAL!Q:Q,$J$4)) -> -
A33: RINGKASAN SEMUA VENDOR (Q2 2026)
A34: No | B34: Vendor | C34: Service | D34: Skor Q1 2026 | E34: Skor Q2 2026 | F34: Status Terkini | G34: Tren
A35: 1 | B35: =HISTORICAL!B4 -> INDOSAT | C35: =HISTORICAL!C4 -> LAYANAN PBX BERBASISKAN CLOUD DENGAN TEKNOLOGI SIP TRUNK | D35: =IF(HISTORICAL!L4="N/A","-",HISTORICAL!L4) -> 3.3184211 | E35: =IF(HISTORICAL!M4="N/A","-",HISTORICAL!M4) -> 3.4394737 | F35: =HISTORICAL!N4 -> Meet Expectation | G35: =IF(OR(NOT(ISNUMBER(D35)),NOT(ISNUMBER(E35))),"-",IF(E35>D35,"▲",IF(E35<D35,"▼","—"))) -> ▲
A36: 2 | B36: =HISTORICAL!B5 -> INFORMASI TEKNOLOGI INDONESIA | C36: =HISTORICAL!C5 -> PENYEDIAAN JASA SMS BROADCAST DAN JASA SMS PULL; CONNECTIVITY PRIMARY LINK | D36: =IF(HISTORICAL!L5="N/A","-",HISTORICAL!L5) -> 3 | E36: =IF(HISTORICAL!M5="N/A","-",HISTORICAL!M5) -> 3 | F36: =HISTORICAL!N5 -> Meet Expectation | G36: =IF(OR(NOT(ISNUMBER(D36)),NOT(ISNUMBER(E36))),"-",IF(E36>D36,"▲",IF(E36<D36,"▼","—"))) -> —
A37: 3 | B37: =HISTORICAL!B6 -> MITRA INTEGRASI INFORMATIKA | C37: =HISTORICAL!C6 -> SFDC MAINTENANCE | D37: =IF(HISTORICAL!L6="N/A","-",HISTORICAL!L6) -> 4.8294872 | E37: =IF(HISTORICAL!M6="N/A","-",HISTORICAL!M6) -> 4.7487179 | F37: =HISTORICAL!N6 -> Exceed Expectation | G37: =IF(OR(NOT(ISNUMBER(D37)),NOT(ISNUMBER(E37))),"-",IF(E37>D37,"▲",IF(E37<D37,"▼","—"))) -> ▼
A38: 4 | B38: =HISTORICAL!B7 -> MULTIFILING MITRA INDONESIA | C38: =HISTORICAL!C7 -> RECORD MANAGEMENT SERVICE | D38: =IF(HISTORICAL!L7="N/A","-",HISTORICAL!L7) -> 3.0318182 | E38: =IF(HISTORICAL!M7="N/A","-",HISTORICAL!M7) -> 3 | F38: =HISTORICAL!N7 -> Meet Expectation | G38: =IF(OR(NOT(ISNUMBER(D38)),NOT(ISNUMBER(E38))),"-",IF(E38>D38,"▲",IF(E38<D38,"▼","—"))) -> ▼
A39: 5 | B39: =HISTORICAL!B8 -> CIPTADRA SOFTINDO | C39: =HISTORICAL!C8 -> PEMELIHARAAN PERANGKAT LUNAK AXITS DAN PERANGKAT LUNAK DMTM | D39: =IF(HISTORICAL!L8="N/A","-",HISTORICAL!L8) -> 4 | E39: =IF(HISTORICAL!M8="N/A","-",HISTORICAL!M8) -> 4.3 | F39: =HISTORICAL!N8 -> Exceed Expectation | G39: =IF(OR(NOT(ISNUMBER(D39)),NOT(ISNUMBER(E39))),"-",IF(E39>D39,"▲",IF(E39<D39,"▼","—"))) -> ▲
A40: 6 | B40: =HISTORICAL!B9 -> INMOTION INOVASI TEKNOLOGI | C40: =HISTORICAL!C9 -> JASA APLIKASI CHATBOT DAN LIVE CHAT | D40: =IF(HISTORICAL!L9="N/A","-",HISTORICAL!L9) -> 4 | E40: =IF(HISTORICAL!M9="N/A","-",HISTORICAL!M9) -> 4 | F40: =HISTORICAL!N9 -> Exceed Expectation | G40: =IF(OR(NOT(ISNUMBER(D40)),NOT(ISNUMBER(E40))),"-",IF(E40>D40,"▲",IF(E40<D40,"▼","—"))) -> —
A41: 7 | B41: =HISTORICAL!B10 -> SATRIA ANTARAN PRIMA TBK | C41: =HISTORICAL!C10 -> PENGIRIMAN POLIS DOKUMEN DAN PAKET DALAM NEGERI | D41: =IF(HISTORICAL!L10="N/A","-",HISTORICAL!L10) -> 3 | E41: =IF(HISTORICAL!M10="N/A","-",HISTORICAL!M10) -> 3.2383333 | F41: =HISTORICAL!N10 -> Meet Expectation | G41: =IF(OR(NOT(ISNUMBER(D41)),NOT(ISNUMBER(E41))),"-",IF(E41>D41,"▲",IF(E41<D41,"▼","—"))) -> ▲
A42: 8 | B42: =HISTORICAL!B11 -> SATRIA ANTARAN PRIMA TBK | C42: =HISTORICAL!C11 -> MAILING ROOM | D42: =IF(HISTORICAL!L11="N/A","-",HISTORICAL!L11) -> 3.4041667 | E42: =IF(HISTORICAL!M11="N/A","-",HISTORICAL!M11) -> 3.04375 | F42: =HISTORICAL!N11 -> Meet Expectation | G42: =IF(OR(NOT(ISNUMBER(D42)),NOT(ISNUMBER(E42))),"-",IF(E42>D42,"▲",IF(E42<D42,"▼","—"))) -> ▼
A43: 9 | B43: =HISTORICAL!B12 -> TARGET SUKSES SINERGI | C43: =HISTORICAL!C12 -> PENGIRIMAN EMAIL MARKETING AUTOMATION | D43: =IF(HISTORICAL!L12="N/A","-",HISTORICAL!L12) -> 3.9 | E43: =IF(HISTORICAL!M12="N/A","-",HISTORICAL!M12) -> 2.9416667 | F43: =HISTORICAL!N12 -> Below Expectation | G43: =IF(OR(NOT(ISNUMBER(D43)),NOT(ISNUMBER(E43))),"-",IF(E43>D43,"▲",IF(E43<D43,"▼","—"))) -> ▼
A44: 10 | B44: =HISTORICAL!B13 -> WIZ TECHNOLOGY INDONESIA | C44: =HISTORICAL!C13 -> VOICE BOT REMINDER CALL | D44: =IF(HISTORICAL!L13="N/A","-",HISTORICAL!L13) -> - | E44: =IF(HISTORICAL!M13="N/A","-",HISTORICAL!M13) -> 3.0875 | F44: =HISTORICAL!N13 -> Meet Expectation | G44: =IF(OR(NOT(ISNUMBER(D44)),NOT(ISNUMBER(E44))),"-",IF(E44>D44,"▲",IF(E44<D44,"▼","—"))) -> -
A45: 11 | B45: =HISTORICAL!B14 -> KARYAPUTRA SURYAGEMILANG | C45: =HISTORICAL!C14 -> TELEMARKETING REVAMP PROJECT | D45: =IF(HISTORICAL!L14="N/A","-",HISTORICAL!L14) -> 3.0318182 | E45: =IF(HISTORICAL!M14="N/A","-",HISTORICAL!M14) -> 3.5393939 | F45: =HISTORICAL!N14 -> Meet Expectation | G45: =IF(OR(NOT(ISNUMBER(D45)),NOT(ISNUMBER(E45))),"-",IF(E45>D45,"▲",IF(E45<D45,"▼","—"))) -> ▲
A46: 12 | B46: =HISTORICAL!B15 -> ARAH SEJAHTERA ABADI | C46: =HISTORICAL!C15 -> PERJANJIAN SEWA MENYEWA | D46: =IF(HISTORICAL!L15="N/A","-",HISTORICAL!L15) -> 2.9611111 | E46: =IF(HISTORICAL!M15="N/A","-",HISTORICAL!M15) -> - | F46: =HISTORICAL!N15 -> Below Expectation | G46: =IF(OR(NOT(ISNUMBER(D46)),NOT(ISNUMBER(E46))),"-",IF(E46>D46,"▲",IF(E46<D46,"▼","—"))) -> -
... A56: 22 | B56: =HISTORICAL!B25 -> ESHAEL Indonesia | C56: =HISTORICAL!C25 -> Talent Assesment | D56: =IF(HISTORICAL!L25="N/A","-",HISTORICAL!L25) -> - | E56: =IF(HISTORICAL!M25="N/A","-",HISTORICAL!M25) -> 4.6083333 | F56: =HISTORICAL!N25 -> Exceed Expectation | G56: =IF(OR(NOT(ISNUMBER(D56)),NOT(ISNUMBER(E56))),"-",IF(E56>D56,"▲",IF(E56<D56,"▼","—"))) -> -

Sheet HISTORICAL
A1: HISTORICAL PERFORMANCE — TREN SKOR PER VENDOR
A3: No | B3: Vendor | C3: Service Scope | D3: 2024 Q1 | E3: 2024 Q2 | F3: 2024 Q3 | G3: 2024 Q4 | H3: 2025 Q1 | I3: 2025 Q2 | J3: 2025 Q3 | K3: 2025 Q4 | L3: 2026 Q1 | M3: 2026 Q2 | N3: Status Terkini | O3: PIC Q2 2026 | P3: Remarks Q1 2026 | Q3: Remarks Q2 2026 | R3: Search Key
A4: 1 | B4: INDOSAT | C4: LAYANAN PBX BERBASISKAN CLOUD DENGAN TEKNOLOGI SIP TRUNK | D4: 3 | E4: 3 | F4: 2.95 | G4: 3 | H4: 2.345 | I4: 1.99 | J4: 2.72 | K4: 2.9825 | L4: =RESULT!E9 -> 3.3184211 | M4: =IFERROR(VALUE('RESULT Q2'!E9),"N/A") -> 3.4394737 | N4: =IF(ISNUMBER(M4),IF(M4>4.99,"Exceptional",IF(M4>3.99,"Exceed Expectation",IF(M4>=2.99,"Meet Expectation",IF(M4>1.9,"Below Expectation","Unsatisfactory")))),IF(ISNUMBER(L4),IF(L4>4.99,"Exceptional",IF(L4>3.99,"Exceed Expectation",IF(L4>=2.99,"Meet Expectation",IF(L4>1.9,"Below Expectation","Unsatisfactory")))),"N/A")) -> Meet Expectation | O4: =IFERROR('RESULT Q2'!D9,"-") -> Nuril HUDHA | P4: =IFERROR(RESULT!G9,"-") -> The performance is getting better, please keep improve the performance. | Q4: =IFERROR('RESULT Q2'!G9,"-") -> Vendor performance is generally acceptable and aligns with the expected level of service. While the engagement has been positive overall, improvements are needed in feature enhancement, dashboard capabilities, and the regularity of report updates. Better preparation in deployment and timely reporting would help increase the overall value and effectiveness of the service. | R4: =B4&" - "&C4 -> INDOSAT - LAYANAN PBX BERBASISKAN CLOUD DENGAN TEKNOLOGI SIP TRUNK
A5: 2 | B5: INFORMASI TEKNOLOGI INDONESIA | C5: PENYEDIAAN JASA SMS BROADCAST DAN JASA SMS PULL; CONNECTIVITY PRIMARY LINK | D5: 3.78 | E5: 4.21 | F5: 3 | G5: 3 | H5: 3 | I5: 3 | J5: 3 | K5: 3.0818182 | L5: =RESULT!E6 -> 3 | M5: =IFERROR(VALUE('RESULT Q2'!E6),"N/A") -> 3 | N5: =IF(ISNUMBER(M5),IF(M5>4.99,"Exceptional",IF(M5>3.99,"Exceed Expectation",IF(M5>=2.99,"Meet Expectation",IF(M5>1.9,"Below Expectation","Unsatisfactory")))),IF(ISNUMBER(L5),IF(L5>4.99,"Exceptional",IF(L5>3.99,"Exceed Expectation",IF(L5>=2.99,"Meet Expectation",IF(L5>1.9,"Below Expectation","Unsatisfactory")))),"N/A")) -> Meet Expectation | O5: =IFERROR('RESULT Q2'!D6,"-") -> Fifin SARINURLITA | P5: =IFERROR(RESULT!G6,"-") -> Jatis has provided good service throughout this year | Q5: =IFERROR('RESULT Q2'!G6,"-") -> So far, Jatis Vendor has provided good service. Their response time is fast, and they are able to provide effective solutions whenever issues arise | R5: =B5&" - "&C5 -> INFORMASI TEKNOLOGI INDONESIA - PENYEDIAAN JASA SMS BROADCAST DAN JASA SMS PULL; CONNECTIVITY PRIMARY LINK
A6: 3 | B6: MITRA INTEGRASI INFORMATIKA | C6: SFDC MAINTENANCE | D6: 3 | E6: 3 | F6: 3.96 | G6: 3.65 | H6: 3 | I6: 4.4166667 | J6: 4.3538462 | K6: 4.2730769 | L6: =RESULT!E13 -> 4.8294872 | M6: =IFERROR(VALUE('RESULT Q2'!E13),"N/A") -> 4.7487179 | N6: =IF(ISNUMBER(M6),IF(M6>4.99,"Exceptional",IF(M6>3.99,"Exceed Expectation",IF(M6>=2.99,"Meet Expectation",IF(M6>1.9,"Below Expectation","Unsatisfactory")))),IF(ISNUMBER(L6),IF(L6>4.99,"Exceptional",IF(L6>3.99,"Exceed Expectation",IF(L6>=2.99,"Meet Expectation",IF(L6>1.9,"Below Expectation","Unsatisfactory")))),"N/A")) -> Exceed Expectation | O6: =IFERROR('RESULT Q2'!D13,"-") -> Chandra Nugraha PUTRA | P6: =IFERROR(RESULT!G13,"-") -> verall, the level of support has been satisfactory. The improvements carried out were highly effective, and several demands were consistent with the initial assessment and expectations. | Q6: =IFERROR('RESULT Q2'!G13,"-") -> Respons terhadap issue maupun kebutuhan sudah cukup baik dan cepat. Support on-site juga sangat membantu dan responsif. Ke depannya, mungkin dapat lebih rutin memberikan update terkait progress kendala atau perbaikan yang sedang dilakukan, sehingga pihak terkait dapat mengetahui status terbaru dan lebih cepat menentukan langkah selanjutnya. | R6: =B6&" - "&C6 -> MITRA INTEGRASI INFORMATIKA - SFDC MAINTENANCE
A7: 4 | B7: MULTIFILING MITRA INDONESIA | C7: RECORD MANAGEMENT SERVICE | D7: 3 | E7: 4 | F7: 4 | G7: 3.65 | H7: 3 | I7: 3 | J7: 3.9125 | K7: 3.0693182 | L7: =RESULT!E8 -> 3.0318182 | M7: =IFERROR(VALUE('RESULT Q2'!E8),"N/A") -> 3 | N7: =IF(ISNUMBER(M7),IF(M7>4.99,"Exceptional",IF(M7>3.99,"Exceed Expectation",IF(M7>=2.99,"Meet Expectation",IF(M7>1.9,"Below Expectation","Unsatisfactory")))),IF(ISNUMBER(L7),IF(L7>4.99,"Exceptional",IF(L7>3.99,"Exceed Expectation",IF(L7>=2.99,"Meet Expectation",IF(L7>1.9,"Below Expectation","Unsatisfactory")))),"N/A")) -> Meet Expectation | O7: =IFERROR('RESULT Q2'!D8,"-") -> Ibnu KUMALA | P7: =IFERROR(RESULT!G8,"-") -> impprove innovation dan simplyfy process | Q7: =IFERROR('RESULT Q2'!G8,"-") -> .. | R7: =B7&" - "&C7 -> MULTIFILING MITRA INDONESIA - RECORD MANAGEMENT SERVICE
A8: 5 | B8: CIPTADRA SOFTINDO | C8: PEMELIHARAAN PERANGKAT LUNAK AXITS DAN PERANGKAT LUNAK DMTM | D8: 4.9 | E8: 4.73 | F8: 3.38 | G8: 3 | H8: 3.975 | I8: 3.675 | J8: 3.75 | K8: 4.2 | L8: =RESULT!E10 -> 4 | M8: =IFERROR(VALUE('RESULT Q2'!E10),"N/A") -> 4.3 | N8: =IF(ISNUMBER(M8),IF(M8>4.99,"Exceptional",IF(M8>3.99,"Exceed Expectation",IF(M8>=2.99,"Meet Expectation",IF(M8>1.9,"Below Expectation","Unsatisfactory")))),IF(ISNUMBER(L8),IF(L8>4.99,"Exceptional",IF(L8>3.99,"Exceed Expectation",IF(L8>=2.99,"Meet Expectation",IF(L8>1.9,"Below Expectation","Unsatisfactory")))),"N/A")) -> Exceed Expectation | O8: =IFERROR('RESULT Q2'!D10,"-") -> Raninta MAHARDI | P8: =IFERROR(RESULT!G10,"-") -> Performance is Good | Q8: =IFERROR('RESULT Q2'!G10,"-") -> Ciptadra selalu fast response ketika ada incident yang terjadi di DMTM | R8: =B8&" - "&C8 -> CIPTADRA SOFTINDO - PEMELIHARAAN PERANGKAT LUNAK AXITS DAN PERANGKAT LUNAK DMTM
A9: 6 | B9: INMOTION INOVASI TEKNOLOGI | C9: JASA APLIKASI CHATBOT DAN LIVE CHAT | D9: 3 | E9: 3 | F9: 3.09 | G9: 3 | H9: 2.121875 | I9: 2.9890625 | J9: 3 | K9: 3.65 | L9: =RESULT!E12 -> 4 | M9: =IFERROR(VALUE('RESULT Q2'!E12),"N/A") -> 4 | N9: =IF(ISNUMBER(M9),IF(M9>4.99,"Exceptional",IF(M9>3.99,"Exceed Expectation",IF(M9>=2.99,"Meet Expectation",IF(M9>1.9,"Below Expectation","Unsatisfactory")))),IF(ISNUMBER(L9),IF(L9>4.99,"Exceptional",IF(L9>3.99,"Exceed Expectation",IF(L9>=2.99,"Meet Expectation",IF(L9>1.9,"Below Expectation","Unsatisfactory")))),"N/A")) -> Exceed Expectation | O9: =IFERROR('RESULT Q2'!D12,"-") -> Djoko DJOKO | P9: =IFERROR(RESULT!G12,"-") -> continue performing thorough and frequent periodic checks to ensure that during service hours, there are no issues that could disrupt operations and resolve the remaining unresolved 401 issue Berikan umpan balik Anda tentang BizChat | Q9: =IFERROR('RESULT Q2'!G12,"-") -> Tetap up to date dan helpful | R9: =B9&" - "&C9 -> INMOTION INOVASI TEKNOLOGI - JASA APLIKASI CHATBOT DAN LIVE CHAT
A10: 7 | B10: SATRIA ANTARAN PRIMA TBK | C10: PENGIRIMAN POLIS DOKUMEN DAN PAKET DALAM NEGERI | D10: 3.75 | E10: 3.83 | F10: 2.74 | G10: 2.725 | H10: 2.86 | I10: 2.6166667 | J10: 2.5 | K10: 2.9611111 | L10: =RESULT!E7 -> 3 | M10: =IFERROR(VALUE('RESULT Q2'!E7),"N/A") -> 3.2383333 | N10: =IF(ISNUMBER(M10),IF(M10>4.99,"Exceptional",IF(M10>3.99,"Exceed Expectation",IF(M10>=2.99,"Meet Expectation",IF(M10>1.9,"Below Expectation","Unsatisfactory")))),IF(ISNUMBER(L10),IF(L10>4.99,"Exceptional",IF(L10>3.99,"Exceed Expectation",IF(L10>=2.99,"Meet Expectation",IF(L10>1.9,"Below Expectation","Unsatisfactory")))),"N/A")) -> Meet Expectation | O10: =IFERROR('RESULT Q2'!D7,"-") -> Fifin SARINURLITA, Novia Laras SANTI | P10: =IFERROR(RESULT!G7,"-") -> SAP has provided excellent service throughout this year | Q10: =IFERROR('RESULT Q2'!G7,"-") -> SAP has shown improvement in terms of reporting and provides a fast response whenever issues arise. | 1. untuk detail status pengiriman dokumen/barang harus diberikan keterangan penerima dengan lengkap dan jelas; 2. Maks. SLA pengiriman harus memenuhi sesuai dengan yang ditetapkan yaitu <5% not meet SLA; 3. Invoice biaya pengiriman dikirimkan ke user yang sesuai dan dikirimkan tidak melebihi periode yang ditetapkan. 4. Report Stock sesuai dengan real stock di warehouse. | R10: =B10&" - "&C10 -> SATRIA ANTARAN PRIMA TBK - PENGIRIMAN POLIS DOKUMEN DAN PAKET DALAM NEGERI
A11: 8 | B11: SATRIA ANTARAN PRIMA TBK | C11: MAILING ROOM | H11: 3 | J11: 3.9125 | K11: 3.05 | L11: =RESULT!E5 -> 3.4041667 | M11: =IFERROR(VALUE('RESULT Q2'!E5),"N/A") -> 3.04375 | N11: =IF(ISNUMBER(M11),IF(M11>4.99,"Exceptional",IF(M11>3.99,"Exceed Expectation",IF(M11>=2.99,"Meet Expectation",IF(M11>1.9,"Below Expectation","Unsatisfactory")))),IF(ISNUMBER(L11),IF(L11>4.99,"Exceptional",IF(L11>3.99,"Exceed Expectation",IF(L11>=2.99,"Meet Expectation",IF(L11>1.9,"Below Expectation","Unsatisfactory")))),"N/A")) -> Meet Expectation | O11: =IFERROR('RESULT Q2'!D5,"-") -> Ibnu KUMALA | P11: =IFERROR(RESULT!G5,"-") -> Over all mailing ok, please improve coordinated with Headoffice team for reduce complain/misscomm (ex case overseas shipment ) | Q11: =IFERROR('RESULT Q2'!G5,"-") -> improve inisiatsis | R11: =B11&" - "&C11 -> SATRIA ANTARAN PRIMA TBK - MAILING ROOM
A12: 9 | B12: TARGET SUKSES SINERGI | C12: PENGIRIMAN EMAIL MARKETING AUTOMATION | D12: 2.85 | E12: 3.28 | F12: 4 | G12: 3.3125 | H12: 3.7444444 | I12: 4 | J12: 3 | K12: 3.65 | L12: =RESULT!E11 -> 3.9 | M12: =IFERROR(VALUE('RESULT Q2'!E11),"N/A") -> 2.9416667 | N12: =IF(ISNUMBER(M12),IF(M12>4.99,"Exceptional",IF(M12>3.99,"Exceed Expectation",IF(M12>=2.99,"Meet Expectation",IF(M12>1.9,"Below Expectation","Unsatisfactory")))),IF(ISNUMBER(L12),IF(L12>4.99,"Exceptional",IF(L12>3.99,"Exceed Expectation",IF(L12>=2.99,"Meet Expectation",IF(L12>1.9,"Below Expectation","Unsatisfactory")))),"N/A")) -> Below Expectation | O12: =IFERROR('RESULT Q2'!D11,"-") -> Bella Friska DEPARI | P12: =IFERROR(RESULT!G11,"-") -> Harganya buat next contrac please murahin ya | Q12: =IFERROR('RESULT Q2'!G11,"-") -> Secara keseluruhan, MTarget telah memberikan dukungan yang baik dalam operasional email campaign dan responsif dalam menangani kebutuhan maupun isu yang muncul. Namun, insiden kesalahan pengiriman email yang terjadi menunjukkan perlunya penguatan pada proses deployment, pengujian, serta validasi sebelum implementasi ke production. Ke depannya, kami berharap MTarget dapat memperkuat proses change management, quality assurance, dan kontrol terhadap segmentasi serta pengiriman email untuk meminimalkan risiko terjadinya insiden serupa. | R12: =B12&" - "&C12 -> TARGET SUKSES SINERGI - PENGIRIMAN EMAIL MARKETING AUTOMATION
A13: 10 | B13: WIZ TECHNOLOGY INDONESIA | C13: VOICE BOT REMINDER CALL | D13: 3 | E13: 3.61 | F13: 3.4 | G13: 3.0875 | H13: 3.0388889 | I13: 3.5444444 | J13: 3 | K13: 3.46875 | L13: N/A | M13: =IFERROR(VALUE('RESULT Q2'!E19),"N/A") -> 3.0875 | N13: =IF(ISNUMBER(M13),IF(M13>4.99,"Exceptional",IF(M13>3.99,"Exceed Expectation",IF(M13>=2.99,"Meet Expectation",IF(M13>1.9,"Below Expectation","Unsatisfactory")))),IF(ISNUMBER(L13),IF(L13>4.99,"Exceptional",IF(L13>3.99,"Exceed Expectation",IF(L13>=2.99,"Meet Expectation",IF(L13>1.9,"Below Expectation","Unsatisfactory")))),"N/A")) -> Meet Expectation | O13: =IFERROR('RESULT Q2'!D19,"-") -> Ravika OKTAVIANI | P13: - | Q13: =IFERROR('RESULT Q2'!G19,"-") -> To ensure a smooth process, we need to move faster and maintain effective communication | R13: =B13&" - "&C13 -> WIZ TECHNOLOGY INDONESIA - VOICE BOT REMINDER CALL
A14: 11 | B14: KARYAPUTRA SURYAGEMILANG | C14: TELEMARKETING REVAMP PROJECT | D14: 3.46 | E14: 3.46 | F14: 3.86 | G14: 3 | H14: 3.1807692 | I14: 2.9371795 | J14: 2.4272727 | K14: 3.5181818 | L14: =RESULT!E19 -> 3.0318182 | M14: =IFERROR(VALUE('RESULT Q2'!E18),"N/A") -> 3.5393939 | N14: =IF(ISNUMBER(M14),IF(M14>4.99,"Exceptional",IF(M14>3.99,"Exceed Expectation",IF(M14>=2.99,"Meet Expectation",IF(M14>1.9,"Below Expectation","Unsatisfactory")))),IF(ISNUMBER(L14),IF(L14>4.99,"Exceptional",IF(L14>3.99,"Exceed Expectation",IF(L14>=2.99,"Meet Expectation",IF(L14>1.9,"Below Expectation","Unsatisfactory")))),"N/A")) -> Meet Expectation | O14: =IFERROR('RESULT Q2'!D18,"-") -> Nuril HUDHA | P14: =IFERROR(RESULT!G19,"-") -> Diharapkan untuk tim project yang diassign apabila CR sudah di signoff agar availibility dari resource ready | Q14: =IFERROR('RESULT Q2'!G18,"-") -> 1. For AI Implementation, KPSG need to improve the delivery time, quality and PIC availability and backup PIC support 2. Another enhancement need to speed up with dedicated team | R14: =B14&" - "&C14 -> KARYAPUTRA SURYAGEMILANG - TELEMARKETING REVAMP PROJECT
A15: 12 | B15: ARAH SEJAHTERA ABADI | C15: PERJANJIAN SEWA MENYEWA | E15: 3 | F15: 3 | G15: 3.35 | H15: 2.8409091 | I15: 2.7727273 | J15: 2 | K15: 2.9611111 | L15: =RESULT!E16 -> 2.9611111 | M15: =IFERROR(VALUE('RESULT Q2'!E23),"N/A") -> N/A | N15: =IF(ISNUMBER(M15),IF(M15>4.99,"Exceptional",IF(M15>3.99,"Exceed Expectation",IF(M15>=2.99,"Meet Expectation",IF(M15>1.9,"Below Expectation","Unsatisfactory")))),IF(ISNUMBER(L15),IF(L15>4.99,"Exceptional",IF(L15>3.99,"Exceed Expectation",IF(L15>=2.99,"Meet Expectation",IF(L15>1.9,"Below Expectation","Unsatisfactory")))),"N/A")) -> Below Expectation | O15: =IFERROR('RESULT Q2'!D23,"-") -> ibnu.kumala@axa-mandiri.co.id | P15: =IFERROR(RESULT!G16,"-") -> Improve quality service, specially for leakage, | Q15: =IFERROR('RESULT Q2'!G23,"-") -> - | R15: =B15&" - "&C15 -> ARAH SEJAHTERA ABADI - PERJANJIAN SEWA MENYEWA
A16: 13 | B16: DELOITTE CONSULTING | C16: DATA PRIVACY TOOLS & PELATIHAN PERSONAL DATA PROTECTION (PDP) | G16: 3.2333333 | H16: 2.9708333 | I16: 2.8833333 | J16: 3.1 | K16: 3.1166667 | L16: =RESULT!E17 -> 3.1636364 | M16: =IFERROR(VALUE('RESULT Q2'!E16),"N/A") -> 4.0636364 | N16: =IF(ISNUMBER(M16),IF(M16>4.99,"Exceptional",IF(M16>3.99,"Exceed Expectation",IF(M16>=2.99,"Meet Expectation",IF(M16>1.9,"Below Expectation","Unsatisfactory")))),IF(ISNUMBER(L16),IF(L16>4.99,"Exceptional",IF(L16>3.99,"Exceed Expectation",IF(L16>=2.99,"Meet Expectation",IF(L16>1.9,"Below Expectation","Unsatisfactory")))),"N/A")) -> Exceed Expectation | O16: =IFERROR('RESULT Q2'!D16,"-") -> M. Andrian Patria Shaleh RIZAL | P16: =IFERROR(RESULT!G17,"-") -> Need more improvement regarding initiative to take mitigation/preventive action to prevent the problem from recurring/current issue. | Q16: =IFERROR('RESULT Q2'!G16,"-") -> In dealing with Security AI-related issues, Deloitte is occasionally unable to provide a resolution and therefore redirects the matter to the Security AI team. Furthermore, several system features are restricted, and these limitations were not clearly communicated at the outset. Consequently, this has created challenges in implementing system enhancements and aligning the system with the business requirements of Security AI users. | R16: =B16&" - "&C16 -> DELOITTE CONSULTING - DATA PRIVACY TOOLS & PELATIHAN PERSONAL DATA PROTECTION (PDP)
A17: 14 | B17: SUTRA MANAGEMENT CONSULTANCIES | C17: IMPLEMENTASI SAS IFRS17 | H17: 3.1866667 | I17: 3.6733333 | J17: 3.5166667 | K17: 3.8666667 | L17: =RESULT!E14 -> 3.6833333 | M17: =IFERROR(VALUE('RESULT Q2'!E14),"N/A") -> 3.3333333 | N17: =IF(ISNUMBER(M17),IF(M17>4.99,"Exceptional",IF(M17>3.99,"Exceed Expectation",IF(M17>=2.99,"Meet Expectation",IF(M17>1.9,"Below Expectation","Unsatisfactory")))),IF(ISNUMBER(L17),IF(L17>4.99,"Exceptional",IF(L17>3.99,"Exceed Expectation",IF(L17>=2.99,"Meet Expectation",IF(L17>1.9,"Below Expectation","Unsatisfactory")))),"N/A")) -> Meet Expectation | O17: =IFERROR('RESULT Q2'!D14,"-") -> Tatang SUTIAMAN | P17: =IFERROR(RESULT!G14,"-") -> Local vendor Sutra is affiliated with SAS Technology which is known as more expensive system compared to other vendors during the Vendor Bidding Process. However, SAS Technology System has been used in few well-known insurance companies in Indonesia, so it is easier to get the review and information; mostly positive. | Q17: =IFERROR('RESULT Q2'!G14,"-") -> no feedback | R17: =B17&" - "&C17 -> SUTRA MANAGEMENT CONSULTANCIES - IMPLEMENTASI SAS IFRS17
A18: 15 | B18: TMF INDONESIA | C18: PAYROLL | L18: =RESULT!E18 -> 3 | M18: =IFERROR(VALUE('RESULT Q2'!E17),"N/A") -> 3 | N18: =IF(ISNUMBER(M18),IF(M18>4.99,"Exceptional",IF(M18>3.99,"Exceed Expectation",IF(M18>=2.99,"Meet Expectation",IF(M18>1.9,"Below Expectation","Unsatisfactory")))),IF(ISNUMBER(L18),IF(L18>4.99,"Exceptional",IF(L18>3.99,"Exceed Expectation",IF(L18>=2.99,"Meet Expectation",IF(L18>1.9,"Below Expectation","Unsatisfactory")))),"N/A")) -> Meet Expectation | O18: =IFERROR('RESULT Q2'!D17,"-") -> Enung HARYATI | P18: =IFERROR(RESULT!G18,"-") -> Always check and recheck the task in internal PIC TMF before send the report to AMFS PIC | Q18: =IFERROR('RESULT Q2'!G17,"-") -> - | R18: =B18&" - "&C18 -> TMF INDONESIA - PAYROLL
A19: 16 | B19: REYCOM DOCUMENT SOLUTION | C19: PRINTING & DMC | L19: =RESULT!E15 -> 4.7666667 | M19: =IFERROR(VALUE('RESULT Q2'!E15),"N/A") -> 4.3 | N19: =IF(ISNUMBER(M19),IF(M19>4.99,"Exceptional",IF(M19>3.99,"Exceed Expectation",IF(M19>=2.99,"Meet Expectation",IF(M19>1.9,"Below Expectation","Unsatisfactory")))),IF(ISNUMBER(L19),IF(L19>4.99,"Exceptional",IF(L19>3.99,"Exceed Expectation",IF(L19>=2.99,"Meet Expectation",IF(L19>1.9,"Below Expectation","Unsatisfactory")))),"N/A")) -> Exceed Expectation | O19: =IFERROR('RESULT Q2'!D15,"-") -> Yulia KURNIATI | P19: =IFERROR(RESULT!G15,"-") -> More inovation for 2026 | Q19: =IFERROR('RESULT Q2'!G15,"-") -> Improvements to their latest Technology to support process at AXA | R19: =B19&" - "&C19 -> REYCOM DOCUMENT SOLUTION - PRINTING & DMC
A20: 17 | B20: FPT METRODATA INDONESIA | C20: PENETRATION TEST | L20: =RESULT!E4 -> 3 | M20: =IFERROR(VALUE('RESULT Q2'!E4),"N/A") -> 4 | N20: =IF(ISNUMBER(M20),IF(M20>4.99,"Exceptional",IF(M20>3.99,"Exceed Expectation",IF(M20>=2.99,"Meet Expectation",IF(M20>1.9,"Below Expectation","Unsatisfactory")))),IF(ISNUMBER(L20),IF(L20>4.99,"Exceptional",IF(L20>3.99,"Exceed Expectation",IF(L20>=2.99,"Meet Expectation",IF(L20>1.9,"Below Expectation","Unsatisfactory")))),"N/A")) -> Exceed Expectation | O20: =IFERROR('RESULT Q2'!D4,"-") -> Fauzi ARYANTO | P20: =IFERROR(RESULT!G4,"-") -> No need improvement | Q20: =IFERROR('RESULT Q2'!G4,"-") -> - | R20: =B20&" - "&C20 -> FPT METRODATA INDONESIA - PENETRATION TEST
A21: 18 | B21: IPROTEKSI TELEMATIKA | C21: PENETRATION TEST | L21: =RESULT!E3 -> 4 | M21: =IFERROR(VALUE('RESULT Q2'!E3),"N/A") -> 4 | N21: =IF(ISNUMBER(M21),IF(M21>4.99,"Exceptional",IF(M21>3.99,"Exceed Expectation",IF(M21>=2.99,"Meet Expectation",IF(M21>1.9,"Below Expectation","Unsatisfactory")))),IF(ISNUMBER(L21),IF(L21>4.99,"Exceptional",IF(L21>3.99,"Exceed Expectation",IF(L21>=2.99,"Meet Expectation",IF(L21>1.9,"Below Expectation","Unsatisfactory")))),"N/A")) -> Exceed Expectation | O21: =IFERROR('RESULT Q2'!D3,"-") -> Fauzi ARYANTO | P21: =IFERROR(RESULT!G3,"-") -> no need improvement | Q21: =IFERROR('RESULT Q2'!G3,"-") -> - | R21: =B21&" - "&C21 -> IPROTEKSI TELEMATIKA - PENETRATION TEST
A22: 19 | B22: ITSEC ASIA | C22: PENETRATION TEST | L22: =RESULT!E2 -> 3 | M22: =IFERROR(VALUE('RESULT Q2'!E2),"N/A") -> 3 | N22: =IF(ISNUMBER(M22),IF(M22>4.99,"Exceptional",IF(M22>3.99,"Exceed Expectation",IF(M22>=2.99,"Meet Expectation",IF(M22>1.9,"Below Expectation","Unsatisfactory")))),IF(ISNUMBER(L22),IF(L22>4.99,"Exceptional",IF(L22>3.99,"Exceed Expectation",IF(L22>=2.99,"Meet Expectation",IF(L22>1.9,"Below Expectation","Unsatisfactory")))),"N/A")) -> Meet Expectation | O22: =IFERROR('RESULT Q2'!D2,"-") -> Fauzi ARYANTO | P22: =IFERROR(RESULT!G2,"-") -> Currently no need improvement | Q22: =IFERROR('RESULT Q2'!G2,"-") -> - | R22: =B22&" - "&C22 -> ITSEC ASIA - PENETRATION TEST
A23: 20 | B23: Karyaputra Suryagemilang | C23: Purecloud Decommisioning | D23: N/A | E23: N/A | F23: N/A | G23: N/A | H23: N/A | I23: N/A | J23: N/A | K23: N/A | L23: N/A | M23: =IFERROR(VALUE('RESULT Q2'!E20),"N/A") -> 3.4458333 | N23: =IF(ISNUMBER(M23),IF(M23>4.99,"Exceptional",IF(M23>3.99,"Exceed Expectation",IF(M23>=2.99,"Meet Expectation",IF(M23>1.9,"Below Expectation","Unsatisfactory")))),"N/A") -> Meet Expectation | O23: =IFERROR('RESULT Q2'!D20,"-") -> Noviani MARBUN | P23: - | Q23: =IFERROR('RESULT Q2'!G20,"-") -> 1. KPSG-ARSI Perspective (The approach applied is still limited to best practices without considering the scenarios occurring in AMFS). 2. Requirement Gap (There is a significant requirement gap due to missed requirements, caused by insufficient exploration of user needs and requirements) 3. Frequent Manpower (MP) and PIC Changes (Manpower changes occur quite frequently, while the implementation team is no longer on-site. The PIC from KPSG also changes often. It is requested that a dedicated PIC be provided for IT Support as well as a dedicated Project Manager) 4. Deployment Issues (Each deployment consistently results in new issues that impact areas outside the deployment scope. This indicates a lack of proper health checks after deployment). 5. Deployment Communication (Communication regarding deployment plans is still lacking, particularly in obtaining approval from business users. This matter has already been communicated by AMFS to the KPSG team). 6. Contact Center Experience (The team’s experience in contact center operations, especially inbound, remains limited). 7. Change Requests (CR) and Production Issues (Many CRs and production issues are delivered based on targets determined unilaterally by KPSG). 8. User Guide and Feature Socialization. (The User Guide is not well maintained. When new features are introduced, documentation should be updated immediately, socialized to users, and the latest User Guide shared to ensure optimal usage) | R23: =B23&" - "&C23 -> Karyaputra Suryagemilang - Purecloud Decommisioning
A24: 21 | B24: Mitra Integrasi Informatika | C24: Purecloud Decommisioning | D24: N/A | E24: N/A | F24: N/A | G24: N/A | H24: N/A | I24: N/A | J24: N/A | K24: N/A | L24: N/A | M24: =IFERROR(VALUE('RESULT Q2'!E21),"N/A") -> 3.8833333 | N24: =IF(ISNUMBER(M24),IF(M24>4.99,"Exceptional",IF(M24>3.99,"Exceed Expectation",IF(M24>=2.99,"Meet Expectation",IF(M24>1.9,"Below Expectation","Unsatisfactory")))),"N/A") -> Meet Expectation | O24: =IFERROR('RESULT Q2'!D21,"-") -> Noviani MARBUN | P24: - | Q24: =IFERROR('RESULT Q2'!G21,"-") -> 1) Training Process During the training sessions, it is expected that explanations are delivered in detail and step by step. When participants are conducting hands-on activities, they should be properly provided with guidance and direct support. This is important to avoid unnecessary questions that could otherwise be answered clearly, ensuring that participants can immediately understand the changes and new features introduced. 2) “Baby Sitting” Phase In the “baby sitting” phase, the MII team was expected to be present full day on-site at AMFS for two weeks. However, in practice, the team did not consistently attend and only joined full day after being specifically requested. As a result, the actual presence was only around five days instead of the full two weeks as originally required. | R24: =B24&" - "&C24 -> Mitra Integrasi Informatika - Purecloud Decommisioning
A25: 22 | B25: ESHAEL Indonesia | C25: Talent Assesment | D25: N/A | E25: N/A | F25: N/A | G25: N/A | H25: N/A | I25: N/A | J25: N/A | K25: N/A | L25: N/A | M25: =IFERROR(VALUE('RESULT Q2'!E22),"N/A") -> 4.6083333 | N25: =IF(ISNUMBER(M25),IF(M25>4.99,"Exceptional",IF(M25>3.99,"Exceed Expectation",IF(M25>=2.99,"Meet Expectation",IF(M25>1.9,"Below Expectation","Unsatisfactory")))),"N/A") -> Exceed Expectation | O25: =IFERROR('RESULT Q2'!D22,"-") -> I Gusti Ayu Mira SETYAWARDHANIE | P25: - | Q25: =IFERROR('RESULT Q2'!G22,"-") -> N/A | R25: =B25&" - "&C25 -> ESHAEL Indonesia - Talent Assesment

Sheet RESULT Q2
A1: No | B1: Vendor | C1: Service | D1: PIC (User) | E1: Total Score | F1: Status | G1: Remarks | H1: Catatan Data
A2: 1 | B2: Itsec Asia | C2: Penetration Testing | D2: Fauzi ARYANTO | E2: ='Q2 ITSEC'!B20 -> 3 | F2: ='Q2 ITSEC'!B21 -> Meet Expectation | G2: ='Q2 ITSEC'!B32 -> -
A3: 2 | B3: Iproteksi Telematika | C3: Penetration Testing | D3: Fauzi ARYANTO | E3: ='Q2 IPROTEKSI'!B20 -> 4 | F3: ='Q2 IPROTEKSI'!B21 -> Exceed Expectation | G3: ='Q2 IPROTEKSI'!B32 -> -
A4: 3 | B4: FPT Metrodata | C4: Penetration Testing | D4: Fauzi ARYANTO | E4: ='Q2 FPT'!B20 -> 4 | F4: ='Q2 FPT'!B21 -> Exceed Expectation | G4: ='Q2 FPT'!B32 -> -
A5: 4 | B5: Satria Antaran Prima | C5: Mailing Room | D5: Ibnu KUMALA | E5: ='Q2 SAP-Mailing'!B25 -> 3.04375 | F5: ='Q2 SAP-Mailing'!B26 -> Meet Expectation | G5: ='Q2 SAP-Mailing'!B37 -> improve inisiatsis
A6: 5 | B6: Informasi Teknologi Indonesia | C6: SMS Broadcast | D6: Fifin SARINURLITA | E6: ='Q2 JATIS'!B29 -> 3 | F6: ='Q2 JATIS'!B30 -> Meet Expectation | G6: ='Q2 JATIS'!B41 -> So far, Jatis Vendor has provided good service. Their response time is fast, and they are able to provide effective solutions whenever issues arise
A7: 6 | B7: Satria Antaran Prima | C7: Courier Service | D7: Fifin SARINURLITA, Novia Laras SANTI | E7: ='Q2 SAP-Courier'!B33 -> 3.2383333 | F7: ='Q2 SAP-Courier'!B34 -> Meet Expectation | G7: ='Q2 SAP-Courier'!B47&" | "&'Q2 SAP-Courier'!B48 -> SAP has shown improvement in terms of reporting and provides a fast response whenever issues arise. | 1. untuk detail status pengiriman dokumen/barang harus diberikan keterangan penerima dengan lengkap dan jelas; 2. Maks. SLA pengiriman harus memenuhi sesuai dengan yang ditetapkan yaitu <5% not meet SLA; 3. Invoice biaya pengiriman dikirimkan ke user yang sesuai dan dikirimkan tidak melebihi periode yang ditetapkan. 4. Report Stock sesuai dengan real stock di warehouse. | H7: Skor rata-rata 2 business user; JAWABAN COMPLIANCE BERBEDA antar user — cek sheet detail.
A8: 7 | B8: Multifiling Mitra Indonesia | C8: Record Management Service | D8: Ibnu KUMALA | E8: ='Q2 MMI'!B29 -> 3 | F8: ='Q2 MMI'!B30 -> Meet Expectation | G8: ='Q2 MMI'!B41 -> ..
A9: 8 | B9: Indosat | C9: Layanan PBX berbasiskan cloud dengan Teknologi SIP Trunk | D9: Nuril HUDHA | E9: ='Q2 INDOSAT'!B36 -> 3.4394737 | F9: ='Q2 INDOSAT'!B37 -> Meet Expectation | G9: ='Q2 INDOSAT'!B48 -> Vendor performance is generally acceptable and aligns with the expected level of service. While the engagement has been positive overall, improvements are needed in feature enhancement, dashboard capabilities, and the regularity of report updates. Better preparation in deployment and timely reporting would help increase the overall value and effectiveness of the service.
A10: 9 | B10: Ciptadra Softindo | C10: Pemeliharaan Axits & DMTM | D10: Raninta MAHARDI | E10: ='Q2 CIPTADRA'!B32 -> 4.3 | F10: ='Q2 CIPTADRA'!B33 -> Exceed Expectation | G10: ='Q2 CIPTADRA'!B44 -> Ciptadra selalu fast response ketika ada incident yang terjadi di DMTM
A11: 10 | B11: Target Sukses Sinergi | C11: Email Marketing Automation | D11: Bella Friska DEPARI | E11: ='Q2 MTARGET'!B23 -> 2.9416667 | F11: ='Q2 MTARGET'!B24 -> Below Expectation | G11: ='Q2 MTARGET'!B35 -> Secara keseluruhan, MTarget telah memberikan dukungan yang baik dalam operasional email campaign dan responsif dalam menangani kebutuhan maupun isu yang muncul. Namun, insiden kesalahan pengiriman email yang terjadi menunjukkan perlunya penguatan pada proses deployment, pengujian, serta validasi sebelum implementasi ke production. Ke depannya, kami berharap MTarget dapat memperkuat proses change management, quality assurance, dan kontrol terhadap segmentasi serta pengiriman email untuk meminimalkan risiko terjadinya insiden serupa.
A12: 11 | B12: Inmotion Inovasi Teknologi | C12: Jasa Aplikasi Chatbot dan Live Chat | D12: Djoko DJOKO | E12: ='Q2 INMOTION'!B54 -> 4 | F12: ='Q2 INMOTION'!B55 -> Exceed Expectation | G12: ='Q2 INMOTION'!B66 -> Tetap up to date dan helpful
A13: 12 | B13: Mitra Integrasi Informatika | C13: SFDC Maintenance | D13: Chandra Nugraha PUTRA | E13: ='Q2 MII-SFDC'!B30 -> 4.7487179 | F13: ='Q2 MII-SFDC'!B31 -> Exceed Expectation | G13: ='Q2 MII-SFDC'!B42 -> Respons terhadap issue maupun kebutuhan sudah cukup baik dan cepat. Support on-site juga sangat membantu dan responsif. Ke depannya, mungkin dapat lebih rutin memberikan update terkait progress kendala atau perbaikan yang sedang dilakukan, sehingga pihak terkait dapat mengetahui status terbaru dan lebih cepat menentukan langkah selanjutnya.
A14: 13 | B14: Sutra Management Consultancies | C14: Implementasi SAS IFRS17 | D14: Tatang SUTIAMAN | E14: ='Q2 SUTRA'!B38 -> 3.3333333 | F14: ='Q2 SUTRA'!B39 -> Meet Expectation | G14: ='Q2 SUTRA'!B50 -> no feedback
A15: 14 | B15: Reycom Document Solution | C15: Printing & Data Management Center | D15: Yulia KURNIATI | E15: ='Q2 RDS-Printing'!B33 -> 4.3 | F15: ='Q2 RDS-Printing'!B34 -> Exceed Expectation | G15: ='Q2 RDS-Printing'!B45 -> Improvements to their latest Technology to support process at AXA | H15: Vendor submit 2x; menggunakan submission terakhir (lebih lengkap).
A16: 15 | B16: Deloitte Consulting | C16: Data Privacy & Pelatihan Personal Data Protection (PDP) | D16: M. Andrian Patria Shaleh RIZAL | E16: ='Q2 DELOITTE'!B28 -> 4.0636364 | F16: ='Q2 DELOITTE'!B29 -> Exceed Expectation | G16: ='Q2 DELOITTE'!B40 -> In dealing with Security AI-related issues, Deloitte is occasionally unable to provide a resolution and therefore redirects the matter to the Security AI team. Furthermore, several system features are restricted, and these limitations were not clearly communicated at the outset. Consequently, this has created challenges in implementing system enhancements and aligning the system with the business requirements of Security AI users.
A17: 16 | B17: TMF Indonesia | C17: Payroll | D17: Enung HARYATI | E17: ='Q2 TMF'!B23 -> 3 | F17: ='Q2 TMF'!B24 -> Meet Expectation | G17: ='Q2 TMF'!B35 -> -
A18: 17 | B18: Karya Putra Surya Gemilang | C18: Telemarketing Revamp Project | D18: Nuril HUDHA | E18: ='Q2 KPSG-TM'!B28 -> 3.5393939 | F18: ='Q2 KPSG-TM'!B29 -> Meet Expectation | G18: ='Q2 KPSG-TM'!B40 -> 1. For AI Implementation, KPSG need to improve the delivery time, quality and PIC availability and backup PIC support 2. Another enhancement need to speed up with dedicated team
A19: 18 | B19: Wiz Technology | C19: Voice Bot Reminder Call | D19: Ravika OKTAVIANI | E19: ='Q2 WIZ'!B25 -> 3.0875 | F19: ='Q2 WIZ'!B26 -> Meet Expectation | G19: ='Q2 WIZ'!B37 -> To ensure a smooth process, we need to move faster and maintain effective communication
A20: 19 | B20: Karyaputra Suryagemilang | C20: Purecloud Decommisioning | D20: Noviani MARBUN | E20: ='Q2 KPSG-ARSI'!B34 -> 3.4458333 | F20: ='Q2 KPSG-ARSI'!B35 -> Meet Expectation | G20: ='Q2 KPSG-ARSI'!B46 -> 1. KPSG-ARSI Perspective (The approach applied is still limited to best practices without considering the scenarios occurring in AMFS). 2. Requirement Gap (There is a significant requirement gap due to missed requirements, caused by insufficient exploration of user needs and requirements) 3. Frequent Manpower (MP) and PIC Changes (Manpower changes occur quite frequently, while the implementation team is no longer on-site. The PIC from KPSG also changes often. It is requested that a dedicated PIC be provided for IT Support as well as a dedicated Project Manager) 4. Deployment Issues (Each deployment consistently results in new issues that impact areas outside the deployment scope. This indicates a lack of proper health checks after deployment). 5. Deployment Communication (Communication regarding deployment plans is still lacking, particularly in obtaining approval from business users. This matter has already been communicated by AMFS to the KPSG team). 6. Contact Center Experience (The team’s experience in contact center operations, especially inbound, remains limited). 7. Change Requests (CR) and Production Issues (Many CRs and production issues are delivered based on targets determined unilaterally by KPSG). 8. User Guide and Feature Socialization. (The User Guide is not well maintained. When new features are introduced, documentation should be updated immediately, socialized to users, and the latest User Guide shared to ensure optimal usage) | H20: Vendor/proyek baru; belum ada histori kuartal sebelumnya. Klasifikasi Quality/Timeline pada pertanyaan custom memakai heuristik kata kunci — mohon di-review SRM.
A21: 20 | B21: Mitra Integrasi Informatika | C21: Purecloud Decommisioning | D21: Noviani MARBUN | E21: ='Q2 MII-Purecloud'!B30 -> 3.8833333 | F21: ='Q2 MII-Purecloud'!B31 -> Meet Expectation | G21: ='Q2 MII-Purecloud'!B42 -> 1) Training Process During the training sessions, it is expected that explanations are delivered in detail and step by step. When participants are conducting hands-on activities, they should be properly provided with guidance and direct support. This is important to avoid unnecessary questions that could otherwise be answered clearly, ensuring that participants can immediately understand the changes and new features introduced. 2) “Baby Sitting” Phase In the “baby sitting” phase, the MII team was expected to be present full day on-site at AMFS for two weeks. However, in practice, the team did not consistently attend and only joined full day after being specifically requested. As a result, the actual presence was only around five days instead of the full two weeks as originally required. | H21: Vendor/proyek baru; belum ada histori kuartal sebelumnya. Klasifikasi Quality/Timeline pada pertanyaan custom memakai heuristik kata kunci — mohon di-review SRM.
A22: 21 | B22: ESHAEL Indonesia | C22: Talent Assesment | D22: I Gusti Ayu Mira SETYAWARDHANIE | E22: ='Q2 ESHAEL'!B29 -> 4.6083333 | F22: ='Q2 ESHAEL'!B30 -> Exceed Expectation | G22: ='Q2 ESHAEL'!B41 -> N/A | H22: Vendor/proyek baru; belum ada histori kuartal sebelumnya. Klasifikasi Quality/Timeline pada pertanyaan custom memakai heuristik kata kunci — mohon di-review SRM.
A23: 22 | B23: Arah Sejahtera Abadi | C23: Perjanjian Sewa Menyewa | D23: ibnu.kumala@axa-mandiri.co.id | E23: N/A | F23: Tidak Dievaluasi Q2 | G23: - | H23: Vendor tidak mengisi assessment pada periode Q2 2026.

Sheet Q2 ITSEC
A1: HASIL REVIEW VENDOR — Q2 2026
A2: Vendor | B2: Itsec Asia
A3: Service | B3: Penetration Testing
A4: PIC (Business User) | B4: Fauzi ARYANTO
A6: No | B6: Dimensi | C6: Pertanyaan | D6: Skor
A7: 1 | B7: Quality | C7: ='RAW DATA Q2 - 1'!ER$1 -> How would you rate the Technical services that is used to penetrate the application which includes: 1. Technical Specification Design. 2. Hardware and capacity sizing for concurrent requests 3. Functi2 | D7: ='RAW DATA Q2 - 1'!ER10 -> 3
A8: 2 | B8: Quality | C8: ='RAW DATA Q2 - 1'!ES$1 -> How would you rate the after sales support capability and methodology?2 | D8: ='RAW DATA Q2 - 1'!ES10 -> 3
A9: 3 | B9: Quality | C9: ='RAW DATA Q2 - 1'!ET$1 -> How would you rate the availability of documentation for product (user manual, troubleshoot document, setup document, etc)?1 | D9: ='RAW DATA Q2 - 1'!ET10 -> 3
A10: 4 | B10: Timeline | C10: ='RAW DATA Q2 - 1'!EU$1 -> How would you rate the supplier's timeliness in delivering goods/services compared to the agreed-upon timeline? | D10: ='RAW DATA Q2 - 1'!EU10 -> 3
A11: 5 | B11: Timeline | C11: ='RAW DATA Q2 - 1'!EV$1 -> How would you rate the supplier's timeliness in sending reports to you? | D11: ='RAW DATA Q2 - 1'!EV10 -> 3
A12: 6 | B12: Timeline | C12: ='RAW DATA Q2 - 1'!EW$1 -> How would you rate the supplier's speed ​​of administrative completion, including completion of contracts draft? | D12: ='RAW DATA Q2 - 1'!EW10 -> 3
A13: 7 | B13: Relationship | C13: ='RAW DATA Q2 - 1'!FM$1 -> How would you rate the supplier's communication with you? | D13: ='RAW DATA Q2 - 1'!FM10 -> 3
A14: 8 | B14: Relationship | C14: ='RAW DATA Q2 - 1'!FN$1 -> How would you rate the supplier's PIC's availability to be contacted when needed? | D14: ='RAW DATA Q2 - 1'!FN10 -> 3
A15: 9 | B15: Relationship | C15: ='RAW DATA Q2 - 1'!FO$1 -> How would you rate the supplier's response speed to you when there are issues? | D15: ='RAW DATA Q2 - 1'!FO10 -> 3
A17: Quality Avg (35%) | B17: =AVERAGEIF(B7:B15,"Quality",D7:D15) -> 3
A18: Timeline Avg (35%) | B18: =AVERAGEIF(B7:B15,"Timeline",D7:D15) -> 3
A19: Relationship Avg (30%) | B19: =AVERAGEIF(B7:B15,"Relationship",D7:D15) -> 3
A20: TOTAL SCORE | B20: =B17*0.35+B18*0.35+B19*0.3 -> 3
A21: STATUS | B21: =IF(B20>4.99,"Exceptional",IF(B20>3.99,"Exceed Expectation",IF(B20>=2.99,"Meet Expectation",IF(B20>1.9,"Below Expectation","Unsatisfactory")))) -> Meet Expectation
A23: DUE DILIGENCE / COMPLIANCE
A24: Financial Assessment | B24: ='RAW DATA Q2 - 1'!FP10 -> Yes
A25: Reputational Assessment | B25: ='RAW DATA Q2 - 1'!FQ10 -> Yes
A26: DPIA | B26: ='RAW DATA Q2 - 1'!FR10 -> Yes, DPIA completed and there are actions to be done by Project Owner
A27: DPSQ | B27: ='RAW DATA Q2 - 1'!FS10 -> No Implementation
A28: VSDDT | B28: ='RAW DATA Q2 - 1'!FT10 -> Yes, VSDDT completed and there are actions to be done by supplier
A29: Action Plan
A31: REMARKS / FEEDBACK
B32: ='RAW DATA Q2 - 1'!FU10 -> -

Sheet Q2 IPROTEKSI
A1: HASIL REVIEW VENDOR — Q2 2026
A2: Vendor | B2: Iproteksi Telematika
A3: Service | B3: Penetration Testing
A4: PIC (Business User) | B4: Fauzi ARYANTO
A6: No | B6: Dimensi | C6: Pertanyaan | D6: Skor
A7: 1 | B7: Quality | C7: ='RAW DATA Q2 - 1'!EO$1 -> How would you rate the Technical services that is used to penetrate the application which includes: 1. Technical Specification Design. 2. Hardware and capacity sizing for concurrent requests 3. Functi1 | D7: ='RAW DATA Q2 - 1'!EO9 -> 4
A8: 2 | B8: Quality | C8: ='RAW DATA Q2 - 1'!EP$1 -> How would you rate the after sales support capability and methodology?1 | D8: ='RAW DATA Q2 - 1'!EP9 -> 4
A9: 3 | B9: Quality | C9: ='RAW DATA Q2 - 1'!EQ$1 -> How would you rate the availability of documentation for product (user manual, troubleshoot document, setup document, etc)? | D9: ='RAW DATA Q2 - 1'!EQ9 -> 4
A10: 4 | B10: Timeline | C10: ='RAW DATA Q2 - 1'!EU$1 -> How would you rate the supplier's timeliness in delivering goods/services compared to the agreed-upon timeline? | D10: ='RAW DATA Q2 - 1'!EU9 -> 4
A11: 5 | B11: Timeline | C11: ='RAW DATA Q2 - 1'!EV$1 -> How would you rate the supplier's timeliness in sending reports to you? | D11: ='RAW DATA Q2 - 1'!EV9 -> 4
A12: 6 | B12: Timeline | C12: ='RAW DATA Q2 - 1'!EW$1 -> How would you rate the supplier's speed ​​of administrative completion, including completion of contracts draft? | D12: ='RAW DATA Q2 - 1'!EW9 -> 4
A13: 7 | B13: Relationship | C13: ='RAW DATA Q2 - 1'!FM$1 -> How would you rate the supplier's communication with you? | D13: ='RAW DATA Q2 - 1'!FM9 -> 4
A14: 8 | B14: Relationship | C14: ='RAW DATA Q2 - 1'!FN$1 -> How would you rate the supplier's PIC's availability to be contacted when needed? | D14: ='RAW DATA Q2 - 1'!FN9 -> 4
A15: 9 | B15: Relationship | C15: ='RAW DATA Q2 - 1'!FO$1 -> How would you rate the supplier's response speed to you when there are issues? | D15: ='RAW DATA Q2 - 1'!FO9 -> 4
A17: Quality Avg (35%) | B17: =AVERAGEIF(B7:B15,"Quality",D7:D15) -> 4
A18: Timeline Avg (35%) | B18: =AVERAGEIF(B7:B15,"Timeline",D7:D15) -> 4
A19: Relationship Avg (30%) | B19: =AVERAGEIF(B7:B15,"Relationship",D7:D15) -> 4
A20: TOTAL SCORE | B20: =B17*0.35+B18*0.35+B19*0.3 -> 4
A21: STATUS | B21: =IF(B20>4.99,"Exceptional",IF(B20>3.99,"Exceed Expectation",IF(B20>=2.99,"Meet Expectation",IF(B20>1.9,"Below Expectation","Unsatisfactory")))) -> Exceed Expectation
A23: DUE DILIGENCE / COMPLIANCE
A24: Financial Assessment | B24: ='RAW DATA Q2 - 1'!FP9 -> Yes
A25: Reputational Assessment | B25: ='RAW DATA Q2 - 1'!FQ9 -> Yes
A26: DPIA | B26: ='RAW DATA Q2 - 1'!FR9 -> Yes, DPIA completed and there are actions to be done by Project Owner
A27: DPSQ | B27: ='RAW DATA Q2 - 1'!FS9 -> No Implementation
A28: VSDDT | B28: ='RAW DATA Q2 - 1'!FT9 -> Yes, VSDDT completed and there are actions to be done by supplier
A29: Action Plan
A31: REMARKS / FEEDBACK
B32: ='RAW DATA Q2 - 1'!FU9 -> -

Sheet Q2 FPT
A1: HASIL REVIEW VENDOR — Q2 2026
A2: Vendor | B2: FPT Metrodata
A3: Service | B3: Penetration Testing
A4: PIC (Business User) | B4: Fauzi ARYANTO
A6: No | B6: Dimensi | C6: Pertanyaan | D6: Skor
A7: 1 | B7: Quality | C7: ='RAW DATA Q2 - 1'!EL$1 -> How would you rate the Technical services that is used to penetrate the application which includes: 1. Technical Specification Design. 2. Hardware and capacity sizing for concurrent requests 3. Functi | D7: ='RAW DATA Q2 - 1'!EL8 -> 4
A8: 2 | B8: Quality | C8: ='RAW DATA Q2 - 1'!EM$1 -> How would you rate the after sales support capability and methodology? | D8: ='RAW DATA Q2 - 1'!EM8 -> 4
A9: 3 | B9: Quality | C9: ='RAW DATA Q2 - 1'!EN$1 -> How would you rate the availability of documentation for service (user manual, troubleshoot document, setup document, etc)? | D9: ='RAW DATA Q2 - 1'!EN8 -> 4
A10: 4 | B10: Timeline | C10: ='RAW DATA Q2 - 1'!EU$1 -> How would you rate the supplier's timeliness in delivering goods/services compared to the agreed-upon timeline? | D10: ='RAW DATA Q2 - 1'!EU8 -> 4
A11: 5 | B11: Timeline | C11: ='RAW DATA Q2 - 1'!EV$1 -> How would you rate the supplier's timeliness in sending reports to you? | D11: ='RAW DATA Q2 - 1'!EV8 -> 4
A12: 6 | B12: Timeline | C12: ='RAW DATA Q2 - 1'!EW$1 -> How would you rate the supplier's speed ​​of administrative completion, including completion of contracts draft? | D12: ='RAW DATA Q2 - 1'!EW8 -> 4
A13: 7 | B13: Relationship | C13: ='RAW DATA Q2 - 1'!FM$1 -> How would you rate the supplier's communication with you? | D13: ='RAW DATA Q2 - 1'!FM8 -> 4
A14: 8 | B14: Relationship | C14: ='RAW DATA Q2 - 1'!FN$1 -> How would you rate the supplier's PIC's availability to be contacted when needed? | D14: ='RAW DATA Q2 - 1'!FN8 -> 4
A15: 9 | B15: Relationship | C15: ='RAW DATA Q2 - 1'!FO$1 -> How would you rate the supplier's response speed to you when there are issues? | D15: ='RAW DATA Q2 - 1'!FO8 -> 4
A17: Quality Avg (35%) | B17: =AVERAGEIF(B7:B15,"Quality",D7:D15) -> 4
A18: Timeline Avg (35%) | B18: =AVERAGEIF(B7:B15,"Timeline",D7:D15) -> 4
A19: Relationship Avg (30%) | B19: =AVERAGEIF(B7:B15,"Relationship",D7:D15) -> 4
A20: TOTAL SCORE | B20: =B17*0.35+B18*0.35+B19*0.3 -> 4
A21: STATUS | B21: =IF(B20>4.99,"Exceptional",IF(B20>3.99,"Exceed Expectation",IF(B20>=2.99,"Meet Expectation",IF(B20>1.9,"Below Expectation","Unsatisfactory")))) -> Exceed Expectation
A23: DUE DILIGENCE / COMPLIANCE
A24: Financial Assessment | B24: ='RAW DATA Q2 - 1'!FP8 -> Yes
A25: Reputational Assessment | B25: ='RAW DATA Q2 - 1'!FQ8 -> Yes
A26: DPIA | B26: ='RAW DATA Q2 - 1'!FR8 -> Yes, DPIA completed and there are actions to be done by Project Owner
A27: DPSQ | B27: ='RAW DATA Q2 - 1'!FS8 -> No Implementation
A28: VSDDT | B28: ='RAW DATA Q2 - 1'!FT8 -> Yes, VSDDT completed and there are actions to be done by supplier
A29: Action Plan
A31: REMARKS / FEEDBACK
B32: ='RAW DATA Q2 - 1'!FU8 -> -

Sheet Q2 SAP-Mailing
A1: HASIL REVIEW VENDOR — Q2 2026
A2: Vendor | B2: Satria Antaran Prima
A3: Service | B3: Mailing Room
A4: PIC (Business User) | B4: Ibnu KUMALA
A6: No | B6: Dimensi | C6: Pertanyaan | D6: Skor
A7: 1 | B7: Quality | C7: ='RAW DATA Q2 - 1'!DX$1 -> How would you rate the goods/services provided by the Supplier against the agreed standards?1 | D7: ='RAW DATA Q2 - 1'!DX11 -> 3
A8: 2 | B8: Quality | C8: ='RAW DATA Q2 - 1'!DY$1 -> How would you rate the accuracy of the data in the Supplier's reports?6 | D8: ='RAW DATA Q2 - 1'!DY11 -> 4
A9: 3 | B9: Quality | C9: ='RAW DATA Q2 - 1'!DZ$1 -> How would you rate overall quality of the work reports provided by the Supplier?6 | D9: ='RAW DATA Q2 - 1'!DZ11 -> 3
A10: 4 | B10: Quality | C10: ='RAW DATA Q2 - 1'!EA$1 -> How would you rate the solutions provided when there is trouble?6 | D10: ='RAW DATA Q2 - 1'!EA11 -> 3
A11: 5 | B11: Quality | C11: ='RAW DATA Q2 - 1'!EB$1 -> How would you rate the resolution to the problem that occurred?6 | D11: ='RAW DATA Q2 - 1'!EB11 -> 3
A12: 6 | B12: Quality | C12: ='RAW DATA Q2 - 1'!EC$1 -> How would you rate the supplier initiative to take mitigation/preventive action to prevent the problem from recurring?7 | D12: ='RAW DATA Q2 - 1'!EC11 -> 3
A13: 7 | B13: Quality | C13: ='RAW DATA Q2 - 1'!ED$1 -> How would you rate the service provided? | D13: ='RAW DATA Q2 - 1'!ED11 -> 3
A14: 8 | B14: Quality | C14: ='RAW DATA Q2 - 1'!EE$1 -> How would you rate the Complaint Handling? | D14: ='RAW DATA Q2 - 1'!EE11 -> 3
A15: 9 | B15: Timeline | C15: ='RAW DATA Q2 - 1'!EU$1 -> How would you rate the supplier's timeliness in delivering goods/services compared to the agreed-upon timeline? | D15: ='RAW DATA Q2 - 1'!EU11 -> 3
A16: 10 | B16: Timeline | C16: ='RAW DATA Q2 - 1'!EV$1 -> How would you rate the supplier's timeliness in sending reports to you? | D16: ='RAW DATA Q2 - 1'!EV11 -> 3
A17: 11 | B17: Timeline | C17: ='RAW DATA Q2 - 1'!EW$1 -> How would you rate the supplier's speed ​​of administrative completion, including completion of contracts draft? | D17: ='RAW DATA Q2 - 1'!EW11 -> 3
A18: 12 | B18: Relationship | C18: ='RAW DATA Q2 - 1'!FM$1 -> How would you rate the supplier's communication with you? | D18: ='RAW DATA Q2 - 1'!FM11 -> 3
A19: 13 | B19: Relationship | C19: ='RAW DATA Q2 - 1'!FN$1 -> How would you rate the supplier's PIC's availability to be contacted when needed? | D19: ='RAW DATA Q2 - 1'!FN11 -> 3
A20: 14 | B20: Relationship | C20: ='RAW DATA Q2 - 1'!FO$1 -> How would you rate the supplier's response speed to you when there are issues? | D20: ='RAW DATA Q2 - 1'!FO11 -> 3
A22: Quality Avg (35%) | B22: =AVERAGEIF(B7:B20,"Quality",D7:D20) -> 3.125
A23: Timeline Avg (35%) | B23: =AVERAGEIF(B7:B20,"Timeline",D7:D20) -> 3
A24: Relationship Avg (30%) | B24: =AVERAGEIF(B7:B20,"Relationship",D7:D20) -> 3
A25: TOTAL SCORE | B25: =B22*0.35+B23*0.35+B24*0.3 -> 3.04375
A26: STATUS | B26: =IF(B25>4.99,"Exceptional",IF(B25>3.99,"Exceed Expectation",IF(B25>=2.99,"Meet Expectation",IF(B25>1.9,"Below Expectation","Unsatisfactory")))) -> Meet Expectation
A28: DUE DILIGENCE / COMPLIANCE
A29: Financial Assessment | B29: ='RAW DATA Q2 - 1'!FP11 -> Yes
A30: Reputational Assessment | B30: ='RAW DATA Q2 - 1'!FQ11 -> Yes
A31: DPIA | B31: ='RAW DATA Q2 - 1'!FR11 -> Yes, DPIA completed and there are actions to be done by Project Owner
A32: DPSQ | B32: ='RAW DATA Q2 - 1'!FS11 -> No Implementation
A33: VSDDT | B33: ='RAW DATA Q2 - 1'!FT11 -> Yes, VSDDT completed and there are actions to be done by supplier
A34: Action Plan
A36: REMARKS / FEEDBACK
B37: ='RAW DATA Q2 - 1'!FU11 -> improve inisiatsis

Sheet Q2 JATIS
A1: HASIL REVIEW VENDOR — Q2 2026
A2: Vendor | B2: Informasi Teknologi Indonesia - SMS Broadcast
A3: Service
A4: PIC (Business User) | B4: Fifin SARINURLITA
A6: No | B6: Dimensi | C6: Pertanyaan | D6: Skor
A7: 1 | B7: Quality | C7: ='RAW DATA Q2 - 1'!AA$1 -> How would you rate Supplier's ability to understand and meet your needs?1 | D7: ='RAW DATA Q2 - 1'!AA5 -> 3
A8: 2 | B8: Quality | C8: ='RAW DATA Q2 - 1'!AB$1 -> How would you rate the goods/services provided by the Supplier against the agreed standards? | D8: ='RAW DATA Q2 - 1'!AB5 -> 3
A9: 3 | B9: Quality | C9: ='RAW DATA Q2 - 1'!AC$1 -> How would you rate the accuracy of the data in the Supplier's reports? | D9: ='RAW DATA Q2 - 1'!AC5 -> 3
A10: 4 | B10: Quality | C10: ='RAW DATA Q2 - 1'!AD$1 -> How would you rate overall quality of the work reports provided by the Supplier? | D10: ='RAW DATA Q2 - 1'!AD5 -> 3
A11: 5 | B11: Quality | C11: ='RAW DATA Q2 - 1'!AE$1 -> How would you rate the solutions provided when there is trouble? | D11: ='RAW DATA Q2 - 1'!AE5 -> 3
A12: 6 | B12: Quality | C12: ='RAW DATA Q2 - 1'!AF$1 -> How would you rate the resolution to the problem that occurred? | D12: ='RAW DATA Q2 - 1'!AF5 -> 3
A13: 7 | B13: Quality | C13: ='RAW DATA Q2 - 1'!AG$1 -> How would you rate the speed of resolution given to problems that occur? | D13: ='RAW DATA Q2 - 1'!AG5 -> 3
A14: 8 | B14: Quality | C14: ='RAW DATA Q2 - 1'!AH$1 -> How would you rate the supplier initiative to take mitigation/preventive action to prevent the problem from recurring? | D14: ='RAW DATA Q2 - 1'!AH5 -> 3
A15: 9 | B15: Quality | C15: ='RAW DATA Q2 - 1'!AI$1 -> How would you rate supplier compliance with administrative processes, including completion of draft cooperation contract?1 | D15: ='RAW DATA Q2 - 1'!AI5 -> 3
A16: 10 | B16: Quality | C16: ='RAW DATA Q2 - 1'!AJ$1 -> How would you rate the Implementation of UAT? | D16: ='RAW DATA Q2 - 1'!AJ5 -> 3
A17: 11 | B17: Quality | C17: ='RAW DATA Q2 - 1'!AK$1 -> How would you rate the maintenance includes bug fixing and support for system problems that occur in the JATIS MOBILE application/service? | D17: ='RAW DATA Q2 - 1'!AK5 -> 3
A18: 12 | B18: Timeline | C18: ='RAW DATA Q2 - 1'!EX$1 -> How would you rate the supplier's timeliness in delivering goods/services compared to the agreed-upon timeline?1 | D18: ='RAW DATA Q2 - 1'!EX5 -> 3
A19: 13 | B19: Timeline | C19: ='RAW DATA Q2 - 1'!EY$1 -> How would you rate the supplier's timeliness in sending reports to you? | D19: ='RAW DATA Q2 - 1'!EY5 -> 3
A20: 14 | B20: Timeline | C20: ='RAW DATA Q2 - 1'!EZ$1 -> How would you rate the supplier's Traffic Confirmation SLA Fulfillment? | D20: ='RAW DATA Q2 - 1'!EZ5 -> 3
A21: 15 | B21: Timeline | C21: ='RAW DATA Q2 - 1'!FA$1 -> How would you rate the supplier's speed ​​of administrative completion, including completion of contracts draft? | D21: ='RAW DATA Q2 - 1'!FA5 -> 3
A22: 16 | B22: Relationship | C22: ='RAW DATA Q2 - 1'!FM$1 -> How would you rate the supplier's communication with you? | D22: ='RAW DATA Q2 - 1'!FM5 -> 3
A23: 17 | B23: Relationship | C23: ='RAW DATA Q2 - 1'!FN$1 -> How would you rate the supplier's PIC's availability to be contacted when needed? | D23: ='RAW DATA Q2 - 1'!FN5 -> 3
